Workbook

Sheet ÖRNEK
A1: 46174 | B1: DADA GÜN SONU RAPORU
C2: GÜNLÜK TOPLAM CİRO | E2: =D4+D5+D6+D7+D8+D9+D10+D11+D12 -> 0 | G2: ÜRÜN DETAYI | H2: ÖDENMEZ İKRAMI KULLANAN ADI SAYADI | I2: ÖDENMEZİN TOPLAM TUTARI
A3: KUVER SAYISI TOPLAMI | D3: ORT.K.BAŞI FİYAT | E3: =E2/C3 -> #DIV/0! | L3: SATIŞ FİYATI
A4: TUZ BİBER BİLET | L4: 150
A5: İTİCKET
A6: PASSO BİLET
A7: BİLETİNİ AL
A8: BİLETİNO MÜŞTERİ SAYISI
A9: BİLETİX MÜŞTERİ SAYISI
A10: BU BİLET MÜŞTERİ SAYISI
A11: CARİ HESAP
A12: SALON SATIŞ KİŞİ SAYISI | C12: =C3-C4-C5-C6-C7-C8-C9-C10-C11 -> 0 | D12: =SUM(D13:E16) -> 0
A13: OTOPARK GELİRİ NAKİT
A14: OTOPARK GELİRİ KREDİ KARTI
A15: GÜNLÜK NAKİT
A16: GÜNLÜK KREDİ KARTI
A17: NAKİT VE KREDİ KARTI TOPLAMI
A19: GÜNLÜK KASADAN HARCAMALAR TOPLAMI | D19: =SUM(D21:E33) -> 0
A20: KASA NAKİT HARCAMA DETAYI | B20: AÇIKLAMA | D20: TUTAR
A34: YÖNETİME TESLİM EDİLMESİ GEREKEN NAKİT TUTAR | D34: =D15+D13-D19 -> 0
A35: KASA TESLİMATI AÇIKLAMASI
A36: KASA AÇILIŞI TUTARI | B36: YÖNETİMDEN GELEN TUTAR | C36: KASA ÇIKIŞI | D36: KASADA OLMASI GEREKEN TUTAR | E36: REEL KASA MEVCUDU | F36: ANA KASA KAPANIŞ FARKI
A37: ='[1]31'!$E$37 -> 17092.5 | C37: =D19 -> 0 | D37: =A37+B37+D15-C37 -> 17092.5 | E37: =D37 -> 17092.5 | F37: =E37-D37 -> 0
A38: CARİ AÇIKLAMASI | B38: DEVİR BAKİYESİ | C38: YENİ ALIM | D38: ÖDEME | E38: SON BAKİYESİ
A39: NURETTİN ATILMIŞ CARİSİ | B39: ='[1]31'!$E$39 -> 691530 | E39: =B39+C39-D39 -> 691530
A40: DAVUL ÜCRETİ CARİSİ | B40: ='[1]31'!$E$40 -> 0 | E40: =B40+C40-D40 -> 0
A41: ÖDENMEZ İKRAM TOPLAMI | E41: =SUM(E43:E68) -> 0
A42: ÖDENMEZ İKRAMI KULLANAN ADI SAYADI | B42: ÇEK NO | C42: ÇEKİN İÇERİĞİ (ÜRÜN DETAYI | E42: ÖDENMEZİN TOPLAM TUTARI
A70: İŞLETME GİDERLERİ DETAYI | B70: TUTAR
A71: SANATÇI GİDERİ
A72: TEKNİK EKİPMAN GİDERLERİ
A73: MATMAZEL COCO
A74: YEMEK GİDERİ BİRLİK GIDA SET MENÜ
A75: İÇECEK KDV Sİ | B75: =B77*0.1568 -> 0
A76: %10 SERVİS ÜCRETİ ÖDENECEK TUTAR
A77: İÇECEK SATIŞ VE ÖDENMEZ MALİYETİ
A78: =A19 -> GÜNLÜK KASADAN HARCAMALAR TOPLAMI | B78: =D19 -> 0
A79: PERSONEL YEMEK 35 ADET
A81: İŞLETME GİDERLERİ | B81: =SUM(B71:B80) -> 0 | C81: =E2-B81 -> 0 | H81: Gn. Toplam | I81: =SUM(I3:I77) -> 0
H82: FARK | I82: =I81-E41 -> 0
...

Sheet 1
A1: 46174 | B1: DADA SALON KABARETT GÜN SONU RAPORU
C2: GÜNLÜK TOPLAM CİRO | E2: =D4+D5+D6+D7+D8+D9+D10+D11+D12 -> 0 | G2: ÜRÜN DETAYI | H2: ÖDENMEZ İKRAMI KULLANAN ADI SAYADI | I2: ÖDENMEZİN TOPLAM TUTARI
A3: KUVER SAYISI TOPLAMI | D3: ORT.K.BAŞI FİYAT | E3: =E2/C3 -> #DIV/0! | L3: SATIŞ FİYATI
A4: TUZ BİBER BİLET
A5: İTİCKET
A6: PASSO BİLET
A7: BİLETİNİ AL
A8: BİLETİNO MÜŞTERİ SAYISI
A9: BİLETİX MÜŞTERİ SAYISI | L9: 150
A10: BU BİLET MÜŞTERİ SAYISI
A11: CARİ HESAP
A12: SALON SATIŞ KİŞİ SAYISI | C12: =C3-C4-C5-C6-C7-C8-C9-C10-C11 -> 0 | D12: =SUM(D13:E16) -> 0
A13: OTOPARK GELİRİ NAKİT
A14: OTOPARK GELİRİ KREDİ KARTI
A15: GÜNLÜK NAKİT
A16: GÜNLÜK KREDİ KARTI
A17: NAKİT VE KREDİ KARTI TOPLAMI
A19: GÜNLÜK KASADAN HARCAMALAR TOPLAMI | D19: =SUM(D21:E33) -> 0
A20: KASA NAKİT HARCAMA DETAYI | B20: AÇIKLAMA | D20: TUTAR
A34: YÖNETİME TESLİM EDİLMESİ GEREKEN NAKİT TUTAR | D34: =D15+D13-D19 -> 0
A35: KASA TESLİMATI AÇIKLAMASI
A36: KASA AÇILIŞI TUTARI | B36: YÖNETİMDEN GELEN TUTAR | C36: KASA ÇIKIŞI | D36: KASADA OLMASI GEREKEN TUTAR | E36: REEL KASA MEVCUDU | F36: ANA KASA KAPANIŞ FARKI
A37: 3748.48 | C37: =D19 -> 0 | D37: =A37+B37+D15-C37 -> 3748.48 | E37: =D37 -> 3748.48 | F37: =E37-D37 -> 0
A38: CARİ AÇIKLAMASI | B38: DEVİR BAKİYESİ | C38: YENİ ALIM | D38: ÖDEME | E38: SON BAKİYESİ
A39: NURETTİN ATILMIŞ CARİSİ | B39: 918220 | E39: =B39+C39-D39 -> 918220
A40: DAVUL ÜCRETİ CARİSİ | B40: 0 | E40: =B40+C40-D40 -> 0
A41: ÖDENMEZ İKRAM TOPLAMI | E41: =SUM(E43:E68) -> 0
A42: ÖDENMEZ İKRAMI KULLANAN ADI SAYADI | B42: ÇEK NO | C42: ÇEKİN İÇERİĞİ (ÜRÜN DETAYI | E42: ÖDENMEZİN TOPLAM TUTARI
A70: İŞLETME GİDERLERİ DETAYI | B70: TUTAR
A71: SANATÇI GİDERİ
A72: TEKNİK EKİPMAN GİDERLERİ
A73: MATMAZEL COCO
A74: YEMEK GİDERİ BİRLİK GIDA SET MENÜ
A75: İÇECEK KDV Sİ | B75: =B77*0.1568 -> 0
A76: %10 SERVİS ÜCRETİ ÖDENECEK TUTAR
A77: İÇECEK SATIŞ VE ÖDENMEZ MALİYETİ
A78: =A19 -> GÜNLÜK KASADAN HARCAMALAR TOPLAMI | B78: =D19 -> 0
A79: PERSONEL YEMEK 35 ADET
A81: İŞLETME GİDERLERİ | B81: =SUM(B71:B80) -> 0 | C81: =E2-B81 -> 0 | H81: Gn. Toplam | I81: =SUM(I3:I77) -> 0
H82: FARK | I82: =I81-E41 -> 0
...

Sheet 2
A1: ='1'!A1+1 -> 46175 | B1: ='1'!B1:E1 -> DADA SALON KABARETT GÜN SONU RAPORU
C2: GÜNLÜK TOPLAM CİRO | E2: =D4+D5+D6+D7+D8+D9+D11+D12 -> 0 | G2: ÜRÜN DETAYI | H2: ÖDENMEZ İKRAMI KULLANAN ADI SAYADI | I2: ÖDENMEZİN TOPLAM TUTARI
A3: KUVER SAYISI TOPLAMI | D3: ORT.K.BAŞI FİYAT | E3: =E2/C3 -> #DIV/0! | L3: SATIŞ FİYATI
A4: TUZ BİBER BİLET
A5: İTİCKET
A6: PASSO BİLET
A7: BİLETİNİ AL
A8: BİLETİNO MÜŞTERİ SAYISI
A9: BİLETİX MÜŞTERİ SAYISI | L9: 150
A10: BU BİLET MÜŞTERİ SAYISI
A11: CARİ HESAP
A12: SALON SATIŞ KİŞİ SAYISI | C12: =C3-C4-C5-C6-C7-C8-C9-C10-C11 -> 0 | D12: =SUM(D13:E16) -> 0
A13: OTOPARK GELİRİ NAKİT
A14: OTOPARK GELİRİ KREDİ KARTI
A15: GÜNLÜK NAKİT
A16: GÜNLÜK KREDİ KARTI
A17: NAKİT VE KREDİ KARTI TOPLAMI
A19: GÜNLÜK KASADAN HARCAMALAR TOPLAMI | D19: =SUM(D21:E33) -> 0
A20: KASA NAKİT HARCAMA DETAYI | B20: AÇIKLAMA | D20: TUTAR
A34: YÖNETİME TESLİM EDİLMESİ GEREKEN NAKİT TUTAR | D34: =D15+D13-D19 -> 0
A35: KASA TESLİMATI AÇIKLAMASI
A36: KASA AÇILIŞI TUTARI | B36: YÖNETİMDEN GELEN TUTAR | C36: KASA ÇIKIŞI | D36: KASADA OLMASI GEREKEN TUTAR | E36: REEL KASA MEVCUDU | F36: ANA KASA KAPANIŞ FARKI
A37: ='1'!E37 -> 3748.48 | C37: =D19 -> 0 | D37: =A37+B37+D15-C37 -> 3748.48 | E37: =D37 -> 3748.48 | F37: =E37-D37 -> 0
A38: CARİ AÇIKLAMASI | B38: DEVİR BAKİYESİ | C38: YENİ ALIM | D38: ÖDEME | E38: SON BAKİYESİ
A39: NURETTİN ATILMIŞ CARİSİ | B39: ='1'!E39 -> 918220 | E39: =B39+C39-D39 -> 918220
A40: DAVUL ÜCRETİ CARİSİ | B40: ='1'!E40 -> 0 | E40: =B40+C40-D40 -> 0
A41: ÖDENMEZ İKRAM TOPLAMI | E41: =SUM(E43:E68) -> 0
A42: ÖDENMEZ İKRAMI KULLANAN ADI SAYADI | B42: ÇEK NO | C42: ÇEKİN İÇERİĞİ (ÜRÜN DETAYI | E42: ÖDENMEZİN TOPLAM TUTARI
A70: İŞLETME GİDERLERİ DETAYI | B70: TUTAR
A71: SANATÇI GİDERİ
A72: TEKNİK EKİPMAN GİDERLERİ
A73: MATMAZEL COCO
A74: YEMEK GİDERİ BİRLİK GIDA 224 SET MENÜ
A75: İÇECEK KDV Sİ | B75: =B77*0.1568 -> 0
A76: %10 SERVİS ÜCRETİ ÖDENECEK TUTAR
A77: İÇECEK SATIŞ VE ÖDENMEZ MALİYETİ
A78: =A19 -> GÜNLÜK KASADAN HARCAMALAR TOPLAMI | B78: =D19 -> 0
A79: PERSONEL YEMEK
A81: İŞLETME GİDERLERİ | B81: =SUM(B71:B80) -> 0 | C81: =E2-B81 -> 0 | H81: Gn. Toplam | I81: =SUM(I3:I77) -> 0
H82: FARK | I82: =I81-E41 -> 0
...

Sheet 3
A1: ='2'!A1+1 -> 46176 | B1: ='1'!B1:E1 -> DADA SALON KABARETT GÜN SONU RAPORU
C2: GÜNLÜK TOPLAM CİRO | E2: =D4+D5+D6+D7+D8+D9+D10+D11+D12 -> 0 | G2: ÜRÜN DETAYI | H2: ÖDENMEZ İKRAMI KULLANAN ADI SAYADI | I2: ÖDENMEZİN TOPLAM TUTARI
A3: KUVER SAYISI TOPLAMI | D3: ORT.K.BAŞI FİYAT | E3: =E2/C3 -> #DIV/0! | L3: SATIŞ FİYATI
A4: TUZ BİBER BİLET
A5: İTİCKET
A6: PASSO BİLET
A7: BİLETİNİ AL | L7: 150
A8: BİLETİNO MÜŞTERİ SAYISI
A9: BİLETİX MÜŞTERİ SAYISI
A10: BU BİLET MÜŞTERİ SAYISI
A11: CARİ HESAP
A12: SALON SATIŞ KİŞİ SAYISI | C12: =C3-C4-C5-C6-C7-C8-C9-C10-C11 -> 0 | D12: =SUM(D13:E16) -> 0
A13: OTOPARK GELİRİ NAKİT
A14: OTOPARK GELİRİ KREDİ KARTI
A15: GÜNLÜK NAKİT
A16: GÜNLÜK KREDİ KARTI
A17: NAKİT VE KREDİ KARTI TOPLAMI
A19: GÜNLÜK KASADAN HARCAMALAR TOPLAMI | D19: =SUM(D21:E33) -> 0
A20: KASA NAKİT HARCAMA DETAYI | B20: AÇIKLAMA | D20: TUTAR
A34: YÖNETİME TESLİM EDİLMESİ GEREKEN NAKİT TUTAR | D34: =D15+D13-D19 -> 0
A35: KASA TESLİMATI AÇIKLAMASI
A36: KASA AÇILIŞI TUTARI | B36: YÖNETİMDEN GELEN TUTAR | C36: KASA ÇIKIŞI | D36: KASADA OLMASI GEREKEN TUTAR | E36: REEL KASA MEVCUDU | F36: ANA KASA KAPANIŞ FARKI
A37: ='2'!E37 -> 3748.48 | C37: =D19 -> 0 | D37: =A37+B37+D15-C37 -> 3748.48 | E37: =D37 -> 3748.48 | F37: =E37-D37 -> 0
A38: CARİ AÇIKLAMASI | B38: DEVİR BAKİYESİ | C38: YENİ ALIM | D38: ÖDEME | E38: SON BAKİYESİ
A39: NURETTİN ATILMIŞ CARİSİ | B39: ='2'!E39 -> 918220 | E39: =B39+C39-D39 -> 918220
A40: DAVUL ÜCRETİ CARİSİ | B40: ='[2]2'!E40 -> 0 | E40: =B40+C40-D40 -> 0
A41: ÖDENMEZ İKRAM TOPLAMI | E41: =SUM(E43:E68) -> 0
A42: ÖDENMEZ İKRAMI KULLANAN ADI SAYADI | B42: ÇEK NO | C42: ÇEKİN İÇERİĞİ (ÜRÜN DETAYI | E42: ÖDENMEZİN TOPLAM TUTARI
A70: İŞLETME GİDERLERİ DETAYI | B70: TUTAR
A71: SANATÇI GİDERİ
A72: TEKNİK EKİPMAN GİDERLERİ
A73: MATMAZEL COCO
A74: YEMEK GİDERİ
A75: İÇECEK KDV Sİ | B75: =B77*0.1568 -> 0
A76: %10 SERVİS ÜCRETİ ÖDENECEK TUTAR
A77: İÇECEK SATIŞ VE ÖDENMEZ MALİYETİ
A78: =A19 -> GÜNLÜK KASADAN HARCAMALAR TOPLAMI | B78: =D19 -> 0
A79: PERSONEL YEMEK 35 ADET
A81: İŞLETME GİDERLERİ | B81: =SUM(B71:B80) -> 0 | C81: =E2-B81 -> 0 | H81: Gn. Toplam | I81: =SUM(I3:I77) -> 0
H82: FARK | I82: =I81-E41 -> 0
...

Sheet 4
A1: ='3'!A1+1 -> 46177 | B1: ='1'!B1:E1 -> DADA SALON KABARETT GÜN SONU RAPORU
C2: GÜNLÜK TOPLAM CİRO | E2: =D4+D5+D6+D7+D8+D9+D10+D11+D12 -> 0 | G2: ÜRÜN DETAYI | H2: ÖDENMEZ İKRAMI KULLANAN ADI SAYADI | I2: ÖDENMEZİN TOPLAM TUTARI
A3: KUVER SAYISI TOPLAMI | D3: ORT.K.BAŞI FİYAT | E3: =E2/C3 -> #DIV/0! | L3: SATIŞ FİYATI
A4: TUZ BİBER BİLET | L4: 150
A5: İTİCKET
A6: PASSO BİLET
A7: BİLETİNİ AL
A8: BİLETİNO MÜŞTERİ SAYISI
A9: BİLETİX MÜŞTERİ SAYISI
A10: BU BİLET MÜŞTERİ SAYISI
A11: CARİ HESAP
A12: SALON SATIŞ KİŞİ SAYISI | C12: =C3-C4-C5-C6-C7-C8-C9-C10-C11 -> 0 | D12: =SUM(D13:E16) -> 0
A13: OTOPARK GELİRİ NAKİT
A14: OTOPARK GELİRİ KREDİ KARTI
A15: GÜNLÜK NAKİT
A16: GÜNLÜK KREDİ KARTI
A17: NAKİT VE KREDİ KARTI TOPLAMI
A19: GÜNLÜK KASADAN HARCAMALAR TOPLAMI | D19: =SUM(D21:E33) -> 0
A20: KASA NAKİT HARCAMA DETAYI | B20: AÇIKLAMA | D20: TUTAR
A34: YÖNETİME TESLİM EDİLEN NAKİT TUTARI | D34: =D15+D13-D19 -> 0
A35: KASA TESLİMATI AÇIKLAMASI
A36: KASA AÇILIŞI TUTARI | B36: YÖNETİMDEN GELEN TUTAR | C36: KASA ÇIKIŞI | D36: KASADA OLMASI GEREKEN TUTAR | E36: REEL KASA MEVCUDU | F36: ANA KASA KAPANIŞ FARKI
A37: ='3'!E37 -> 3748.48 | C37: =D19 -> 0 | D37: =A37+B37+D15-C37 -> 3748.48 | E37: =D37 -> 3748.48 | F37: =E37-D37 -> 0
A38: CARİ AÇIKLAMASI | B38: DEVİR BAKİYESİ | C38: YENİ ALIM | D38: ÖDEME | E38: SON BAKİYESİ
A39: NURETTİN ATILMIŞ CARİSİ | B39: ='3'!E39 -> 918220 | E39: =B39+C39-D39 -> 918220
A40: DAVUL ÜCRETİ CARİSİ | B40: ='3'!E40 -> 0 | E40: =B40+C40-D40 -> 0
A41: ÖDENMEZ İKRAM TOPLAMI | E41: =SUM(E43:E68) -> 0
A42: ÖDENMEZ İKRAMI KULLANAN ADI SAYADI | B42: ÇEK NO | C42: ÇEKİN İÇERİĞİ (ÜRÜN DETAYI | E42: ÖDENMEZİN TOPLAM TUTARI
A70: İŞLETME GİDERLERİ DETAYI | B70: TUTAR
A71: SANATÇI GİDERİ
A72: TEKNİK EKİPMAN GİDERLERİ
A73: MATMAZEL COCO
A74: YEMEK GİDERİ BİRLİK GIDA 117 SET MENÜ
A75: İÇECEK KDV Sİ | B75: =B77*0.1568 -> 0
A76: %10 SERVİS ÜCRETİ ÖDENECEK TUTAR
A77: İÇECEK SATIŞ VE ÖDENMEZ MALİYETİ
A78: =A19 -> GÜNLÜK KASADAN HARCAMALAR TOPLAMI | B78: =D19 -> 0
A79: PERSONEL YEMEK 55 ADET
A81: İŞLETME GİDERLERİ | B81: =SUM(B71:B80) -> 0 | C81: =E2-B81 -> 0 | H81: Gn. Toplam | I81: =SUM(I3:I77) -> 0
H82: FARK | I82: =I81-E41 -> 0
...

Sheet 5
A1: ='4'!A1+1 -> 46178 | B1: ='1'!B1:E1 -> DADA SALON KABARETT GÜN SONU RAPORU
C2: GÜNLÜK TOPLAM CİRO | E2: =D4+D5+D6+D7+D8+D9+D10+D11+D12 -> 268265 | G2: ÜRÜN DETAYI | H2: ÖDENMEZ İKRAMI KULLANAN ADI SAYADI | I2: ÖDENMEZİN TOPLAM TUTARI
A3: KUVER SAYISI TOPLAMI | C3: 45 | D3: ORT.K.BAŞI FİYAT | E3: =E2/C3 -> 5961.4444 | L3: SATIŞ FİYATI
A4: TUZ BİBER BİLET
A5: İTİCKET
A6: PASSO BİLET
A7: BİLETİNİ AL | L7: 150
A8: BİLETİNO MÜŞTERİ SAYISI
A9: BİLETİX MÜŞTERİ SAYISI | C9: 2 | D9: 13000
A10: BU BİLET MÜŞTERİ SAYISI
A11: CARİ HESAP | C11: 5 | D11: 29200
A12: SALON SATIŞ KİŞİ SAYISI | C12: =C3-C4-C5-C6-C7-C8-C9-C10-C11 -> 38 | D12: =SUM(D13:E16) -> 226065
A13: OTOPARK GELİRİ NAKİT
A14: OTOPARK GELİRİ KREDİ KARTI
A15: GÜNLÜK NAKİT
A16: GÜNLÜK KREDİ KARTI | D16: 226065
A17: NAKİT VE KREDİ KARTI TOPLAMI
A19: GÜNLÜK KASADAN HARCAMALAR TOPLAMI | D19: =SUM(D21:E33) -> 39930
A20: KASA NAKİT HARCAMA DETAYI | B20: AÇIKLAMA | D20: TUTAR
B21: PERSONEL YOL | D21: 12250
B22: EXTRA PERSONEL 3 KISI | D22: 6500
B23: HAYATI AKSU | D23: 2000
B24: MASA ORTUSU YIKAMA 32 ADET | D24: 960
B25: 10 ADET LED AMPUL | D25: 1010
B26: KABARET TEMIZLIGI | D26: 1000
B27: ELEKTRIKCIYE SAHNE ISTIRIDYELERI ICIN ÖDEME | D27: 1000
B28: BAR ICIN TOZ SEKER,YUMURTA ALIMI | D28: 615
B29: KOLI BANT 3 ADET | D29: 195
B30: BAR ICIN PEYNIR ALIMI | D30: 14400
A34: YÖNETİME TESLİM EDİLMESİ GEREKEN NAKİT TUTAR | D34: =D15+D13-D19 -> -39930
A35: KASA TESLİMATI AÇIKLAMASI
A36: KASA AÇILIŞI TUTARI | B36: YÖNETİMDEN GELEN TUTAR | C36: KASA ÇIKIŞI | D36: KASADA OLMASI GEREKEN TUTAR | E36: REEL KASA MEVCUDU | F36: ANA KASA KAPANIŞ FARKI
A37: ='4'!E37 -> 3748.48 | B37: 40000 | C37: =D19 -> 39930 | D37: =A37+B37+D15-C37 -> 3818.48 | E37: =D37 -> 3818.48 | F37: =E37-D37 -> 0
A38: CARİ AÇIKLAMASI | B38: DEVİR BAKİYESİ | C38: YENİ ALIM | D38: ÖDEME | E38: SON BAKİYESİ
A39: NURETTİN ATILMIŞ CARİSİ | B39: ='4'!E39 -> 918220 | C39: 9900 | E39: =B39+C39-D39 -> 928120
A40: DAVUL ÜCRETİ CARİSİ | B40: ='4'!E40 -> 0 | E40: =B40+C40-D40 -> 0
A41: ÖDENMEZ İKRAM TOPLAMI | E41: =SUM(E43:E68) -> 0
A42: ÖDENMEZ İKRAMI KULLANAN ADI SAYADI | B42: ÇEK NO | C42: ÇEKİN İÇERİĞİ (ÜRÜN DETAYI | E42: ÖDENMEZİN TOPLAM TUTARI
A70: İŞLETME GİDERLERİ DETAYI | B70: TUTAR
A71: SANATÇI GİDERİ | B71: 180000
...

Sheet 6
A1: ='5'!A1+1 -> 46179 | B1: ='1'!B1:E1 -> DADA SALON KABARETT GÜN SONU RAPORU
C2: GÜNLÜK TOPLAM CİRO | E2: =D4+D5+D6+D7+D8+D9+D10+D11+D12 -> 0 | G2: ÜRÜN DETAYI | H2: ÖDENMEZ İKRAMI KULLANAN ADI SAYADI | I2: ÖDENMEZİN TOPLAM TUTARI
A3: KUVER SAYISI TOPLAMI | D3: ORT.K.BAŞI FİYAT | E3: =E2/C3 -> #DIV/0! | L3: SATIŞ FİYATI
A4: TUZ BİBER BİLET
A5: İTİCKET | K5: =144720*1.18 -> 170769.6
A6: PASSO BİLET
A7: BİLETİNİ AL | K7: =K5-D7 -> 170769.6 | L7: 150
A8: BİLETİNO MÜŞTERİ SAYISI
A9: BİLETİX MÜŞTERİ SAYISI
A10: BU BİLET MÜŞTERİ SAYISI
A11: CARİ HESAP
A12: SALON SATIŞ KİŞİ SAYISI | C12: =C3-C4-C5-C6-C7-C8-C9-C10-C11 -> 0 | D12: =SUM(D13:E16) -> 0
A13: OTOPARK GELİRİ NAKİT
A14: OTOPARK GELİRİ KREDİ KARTI
A15: GÜNLÜK NAKİT
A16: GÜNLÜK KREDİ KARTI
A17: NAKİT VE KREDİ KARTI TOPLAMI
A19: GÜNLÜK KASADAN HARCAMALAR TOPLAMI | D19: =SUM(D21:E33) -> 0
A20: KASA NAKİT HARCAMA DETAYI | B20: AÇIKLAMA | D20: TUTAR
A34: YÖNETİME TESLİM EDİLMESİ GEREKEN NAKİT TUTAR | D34: =D15+D13-D19 -> 0 | K34: =93750+20000+10970+20000 -> 144720
A35: KASA TESLİMATI AÇIKLAMASI
A36: KASA AÇILIŞI TUTARI | B36: YÖNETİMDEN GELEN TUTAR | C36: KASA ÇIKIŞI | D36: KASADA OLMASI GEREKEN TUTAR | E36: REEL KASA MEVCUDU | F36: ANA KASA KAPANIŞ FARKI
A37: ='5'!E37 -> 3818.48 | C37: =D19 -> 0 | D37: =A37+B37+D15-C37 -> 3818.48 | E37: =D37 -> 3818.48 | F37: =E37-D37 -> 0
A38: CARİ AÇIKLAMASI | B38: DEVİR BAKİYESİ | C38: YENİ ALIM | D38: ÖDEME | E38: SON BAKİYESİ
A39: NURETTİN ATILMIŞ CARİSİ | B39: ='5'!E39 -> 928120 | E39: =B39+C39-D39 -> 928120
A40: DAVUL ÜCRETİ CARİSİ | B40: ='5'!E40 -> 0 | E40: =B40+C40-D40 -> 0 | K40: =K34*0.18 -> 26049.6
A41: ÖDENMEZ İKRAM TOPLAMI | E41: =SUM(E43:E68) -> 0 | K41: =SUM(K34:K40) -> 170769.6
A42: ÖDENMEZ İKRAMI KULLANAN ADI SAYADI | B42: ÇEK NO | C42: ÇEKİN İÇERİĞİ (ÜRÜN DETAYI | E42: ÖDENMEZİN TOPLAM TUTARI
A70: İŞLETME GİDERLERİ DETAYI | B70: TUTAR
A71: SANATÇI GİDERİ
A72: TEKNİK EKİPMAN GİDERLERİ
A73: MATMAZEL COCO
A74: YEMEK GİDERİ BİRLİK GIDA 203 + 5 DILIM PEYNIR SET MENÜ
A75: İÇECEK KDV Sİ | B75: =B77*0.1568 -> 0
A76: %10 SERVİS ÜCRETİ ÖDENECEK TUTAR
A77: İÇECEK SATIŞ VE ÖDENMEZ MALİYETİ
A78: =A19 -> GÜNLÜK KASADAN HARCAMALAR TOPLAMI | B78: =D19 -> 0
A79: PERSONEL YEMEK 55 ADET
A81: İŞLETME GİDERLERİ | B81: =SUM(B71:B80) -> 0 | C81: =E2-B81 -> 0 | H81: Gn. Toplam | I81: =SUM(I3:I77) -> 0
H82: FARK | I82: =I81-E41 -> 0
...

Sheet 7
A1: ='6'!A1+1 -> 46180 | B1: ='1'!B1:E1 -> DADA SALON KABARETT GÜN SONU RAPORU
C2: GÜNLÜK TOPLAM CİRO | E2: =D4+D5+D6+D7+D8+D9+D10+D11+D12 -> 0 | G2: ÜRÜN DETAYI | H2: ÖDENMEZ İKRAMI KULLANAN ADI SAYADI | I2: ÖDENMEZİN TOPLAM TUTARI
A3: KUVER SAYISI TOPLAMI | D3: ORT.K.BAŞI FİYAT | E3: =E2/C3 -> #DIV/0! | L3: SATIŞ FİYATI
A4: TUZ BİBER BİLET
A5: İTİCKET
A6: PASSO BİLET
A7: BİLETİNİ AL | L7: 150
A8: BİLETİNO MÜŞTERİ SAYISI
A9: BİLETİX MÜŞTERİ SAYISI
A10: BU BİLET MÜŞTERİ SAYISI
A11: CARİ HESAP
A12: SALON SATIŞ KİŞİ SAYISI | C12: =C3-C4-C5-C6-C7-C8-C9-C10-C11 -> 0 | D12: =SUM(D13:E16) -> 0
A13: OTOPARK GELİRİ NAKİT
A14: OTOPARK GELİRİ KREDİ KARTI
A15: GÜNLÜK NAKİT
A16: GÜNLÜK KREDİ KARTI
A17: NAKİT VE KREDİ KARTI TOPLAMI
A19: GÜNLÜK KASADAN HARCAMALAR TOPLAMI | D19: =SUM(D21:E33) -> 0
A20: KASA NAKİT HARCAMA DETAYI | B20: AÇIKLAMA | D20: TUTAR
A34: YÖNETİME TESLİM EDİLMESİ GEREKEN NAKİT TUTAR | D34: =D15+D13-D19 -> 0
A35: KASA TESLİMATI AÇIKLAMASI
A36: KASA AÇILIŞI TUTARI | C36: KASA ÇIKIŞI | D36: KASADA OLMASI GEREKEN TUTAR | E36: REEL KASA MEVCUDU | F36: ANA KASA KAPANIŞ FARKI
A37: ='6'!E37 -> 3818.48 | C37: =D19 -> 0 | D37: =A37+B37+D15-C37 -> 3818.48 | E37: =D37 -> 3818.48 | F37: =E37-D37 -> 0
A38: CARİ AÇIKLAMASI | B38: DEVİR BAKİYESİ | C38: YENİ ALIM | D38: ÖDEME | E38: SON BAKİYESİ
A39: NURETTİN ATILMIŞ CARİSİ | B39: ='6'!E39 -> 928120 | E39: =B39+C39-D39 -> 928120
A40: DAVUL ÜCRETİ CARİSİ | B40: ='6'!E40 -> 0 | E40: =B40+C40-D40 -> 0
A41: ÖDENMEZ İKRAM TOPLAMI | E41: =SUM(E43:E68) -> 0
A42: ÖDENMEZ İKRAMI KULLANAN ADI SAYADI | B42: ÇEK NO | C42: ÇEKİN İÇERİĞİ (ÜRÜN DETAYI | E42: ÖDENMEZİN TOPLAM TUTARI
A70: İŞLETME GİDERLERİ DETAYI | B70: TUTAR
A71: SANATÇI GİDERİ
A72: TEKNİK EKİPMAN GİDERLERİ
A73: MATMAZEL COCO
A74: YEMEK GİDERİ BİRLİK GIDA 124 SET MENÜ+ 15 DILIM PEYNIR + 1 SET MEZE
A75: İÇECEK KDV Sİ | B75: =B77*0.1568 -> 0
A76: %10 SERVİS ÜCRETİ ÖDENECEK TUTAR
A77: İÇECEK SATIŞ VE ÖDENMEZ MALİYETİ
A78: =A19 -> GÜNLÜK KASADAN HARCAMALAR TOPLAMI | B78: =D19 -> 0
A79: PERSONEL YEMEK 60 ADET
A81: İŞLETME GİDERLERİ | B81: =SUM(B71:B80) -> 0 | C81: =E2-B81 -> 0 | H81: Gn. Toplam | I81: =SUM(I3:I77) -> 0
H82: FARK | I82: =I81-E41 -> 0
...

Sheet 8
A1: ='7'!A1+1 -> 46181 | B1: ='[3]1'!B1:E1 -> DADA SALON GÜN SONU RAPORU
C2: GÜNLÜK TOPLAM CİRO | E2: =D4+D5+D6+D7+D8+D9+D10+D11+D12 -> 0 | G2: ÜRÜN DETAYI | H2: ÖDENMEZ İKRAMI KULLANAN ADI SAYADI | I2: ÖDENMEZİN TOPLAM TUTARI
A3: KUVER SAYISI TOPLAMI | D3: ORT.K.BAŞI FİYAT | E3: =E2/C3 -> #DIV/0! | L3: SATIŞ FİYATI
A4: TUZ BİBER BİLET
A5: İTİCKET
A6: PASSO BİLET
A7: BİLETİNİ AL | L7: 150
A8: BİLETİNO MÜŞTERİ SAYISI
A9: BİLETİX MÜŞTERİ SAYISI
A10: BU BİLET MÜŞTERİ SAYISI
A11: CARİ HESAP
A12: SALON SATIŞ KİŞİ SAYISI | C12: =C3-C4-C5-C6-C7-C8-C9-C10-C11 -> 0 | D12: =SUM(D13:E16) -> 0
A13: OTOPARK GELİRİ NAKİT
A14: OTOPARK GELİRİ KREDİ KARTI
A15: GÜNLÜK NAKİT
A16: GÜNLÜK KREDİ KARTI
A17: NAKİT VE KREDİ KARTI TOPLAMI
A19: GÜNLÜK KASADAN HARCAMALAR TOPLAMI | D19: =SUM(D21:E33) -> 0
A20: KASA NAKİT HARCAMA DETAYI | B20: AÇIKLAMA | D20: TUTAR
A34: YÖNETİME TESLİM EDİLMESİ GEREKEN NAKİT TUTAR | D34: =D15+D13-D19 -> 0
A35: KASA TESLİMATI AÇIKLAMASI
A36: KASA AÇILIŞI TUTARI | B36: YÖNETİMDEN GELEN TUTAR | C36: KASA ÇIKIŞI | D36: KASADA OLMASI GEREKEN TUTAR | E36: REEL KASA MEVCUDU | F36: ANA KASA KAPANIŞ FARKI
A37: ='7'!E37 -> 3818.48 | C37: =D19 -> 0 | D37: =A37+B37+D15-C37 -> 3818.48 | E37: =D37 -> 3818.48 | F37: =E37-D37 -> 0
A38: CARİ AÇIKLAMASI | B38: DEVİR BAKİYESİ | C38: YENİ ALIM | D38: ÖDEME | E38: SON BAKİYESİ
A39: NURETTİN ATILMIŞ CARİSİ | B39: ='7'!E39 -> 928120 | E39: =B39+C39-D39 -> 928120
A40: DAVUL ÜCRETİ CARİSİ | B40: ='7'!E40 -> 0 | E40: =B40+C40-D40 -> 0
A41: ÖDENMEZ İKRAM TOPLAMI | E41: =SUM(E43:E68) -> 0
A42: ÖDENMEZ İKRAMI KULLANAN ADI SAYADI | B42: ÇEK NO | C42: ÇEKİN İÇERİĞİ (ÜRÜN DETAYI | E42: ÖDENMEZİN TOPLAM TUTARI
A70: İŞLETME GİDERLERİ DETAYI | B70: TUTAR
A71: SANATÇI GİDERİ
A72: TEKNİK EKİPMAN GİDERLERİ ,30 BİSTRO,60 SANDELYE ,PHOTOBOOTH ,LED EKRAN, ,DJ KABİN
A73: MATMAZEL COCO
A74: YEMEK GİDERİ HOME STYLE KOKTEYL MENÜ 250 KISILIK
A75: İÇECEK KDV Sİ | B75: =B77*0.1568 -> 0
A76: %10 SERVİS ÜCRETİ ÖDENECEK TUTAR
A77: İÇECEK SATIŞ VE ÖDENMEZ MALİYETİ
A78: =A19 -> GÜNLÜK KASADAN HARCAMALAR TOPLAMI | B78: =D19 -> 0
A79: PERSONEL YEMEK
A81: İŞLETME GİDERLERİ | B81: =SUM(B71:B80) -> 0 | C81: =E2-B81 -> 0 | H81: Gn. Toplam | I81: =SUM(I3:I77) -> 0
H82: FARK | I82: =I81-E41 -> 0
...

Sheet 9
A1: ='8'!A1+1 -> 46182 | B1: ='1'!B1:E1 -> DADA SALON KABARETT GÜN SONU RAPORU
C2: GÜNLÜK TOPLAM CİRO | E2: =D4+D5+D6+D7+D8+D9+D10+D11+D12 -> 0 | G2: ÜRÜN DETAYI | H2: ÖDENMEZ İKRAMI KULLANAN ADI SAYADI | I2: ÖDENMEZİN TOPLAM TUTARI
A3: KUVER SAYISI TOPLAMI | D3: ORT.K.BAŞI FİYAT | E3: =E2/C3 -> #DIV/0! | L3: SATIŞ FİYATI
A4: TUZ BİBER BİLET
A5: İTİCKET
A6: PASSO BİLET
A7: BİLETİNİ AL | L7: 150
A8: BİLETİNO MÜŞTERİ SAYISI
A9: BİLETİX MÜŞTERİ SAYISI
A10: BU BİLET MÜŞTERİ SAYISI
A11: CARİ HESAP
A12: SALON SATIŞ KİŞİ SAYISI | C12: =C3-C4-C5-C6-C7-C8-C9-C10-C11 -> 0 | D12: =SUM(D13:E16) -> 0
A13: OTOPARK GELİRİ NAKİT
A14: OTOPARK GELİRİ KREDİ KARTI
A15: GÜNLÜK NAKİT
A16: GÜNLÜK KREDİ KARTI
A17: NAKİT VE KREDİ KARTI TOPLAMI
A19: GÜNLÜK KASADAN HARCAMALAR TOPLAMI | D19: =SUM(D21:E33) -> 0
A20: KASA NAKİT HARCAMA DETAYI | B20: AÇIKLAMA | D20: TUTAR
A34: YÖNETİME TESLİM EDİLMESİ GEREKEN NAKİT TUTAR | D34: =D15+D13-D19 -> 0
A35: KASA TESLİMATI AÇIKLAMASI
A36: KASA AÇILIŞI TUTARI | B36: YÖNETİMDEN GELEN TUTAR | C36: KASA ÇIKIŞI | D36: KASADA OLMASI GEREKEN TUTAR | E36: REEL KASA MEVCUDU | F36: ANA KASA KAPANIŞ FARKI
A37: ='8'!E37 -> 3818.48 | C37: =D19 -> 0 | D37: =A37+B37+D15-C37 -> 3818.48 | E37: =D37 -> 3818.48 | F37: =E37-D37 -> 0
A38: CARİ AÇIKLAMASI | B38: DEVİR BAKİYESİ | C38: YENİ ALIM | D38: ÖDEME | E38: SON BAKİYESİ
A39: NURETTİN ATILMIŞ CARİSİ | B39: ='8'!E39 -> 928120 | E39: =B39+C39-D39 -> 928120
A40: DAVUL ÜCRETİ CARİSİ | B40: ='8'!E40 -> 0 | E40: =B40+C40-D40 -> 0
A41: ÖDENMEZ İKRAM TOPLAMI | E41: =SUM(E43:E68) -> 0
A42: ÖDENMEZ İKRAMI KULLANAN ADI SAYADI | B42: ÇEK NO | C42: ÇEKİN İÇERİĞİ (ÜRÜN DETAYI | E42: ÖDENMEZİN TOPLAM TUTARI
A70: İŞLETME GİDERLERİ DETAYI | B70: TUTAR
A71: SANATÇI GİDERİ
A72: TEKNİK EKİPMAN GİDERLERİ
A73: MATMAZEL COCO
A74: YEMEK GİDERİ BİRLİK GIDA 133 SET MENÜ
A75: İÇECEK KDV Sİ | B75: 0
A76: %10 SERVİS ÜCRETİ ÖDENECEK TUTAR
A77: İÇECEK SATIŞ VE ÖDENMEZ MALİYETİ
A78: =A19 -> GÜNLÜK KASADAN HARCAMALAR TOPLAMI | B78: =D19 -> 0
A79: PERSONEL YEMEK 55 ADET
A81: İŞLETME GİDERLERİ | B81: =SUM(B71:B80) -> 0 | C81: =E2-B81 -> 0 | H81: Gn. Toplam | I81: =SUM(I3:I77) -> 0
H82: FARK | I82: =I81-E41 -> 0
...

Sheet 10
A1: ='9'!A1+1 -> 46183 | B1: ='1'!B1:E1 -> DADA SALON KABARETT GÜN SONU RAPORU
C2: GÜNLÜK TOPLAM CİRO | E2: =D4+D5+D6+D7+D8+D9+D10+D11+D12 -> 0 | G2: ÜRÜN DETAYI | H2: ÖDENMEZ İKRAMI KULLANAN ADI SAYADI | I2: ÖDENMEZİN TOPLAM TUTARI
A3: KUVER SAYISI TOPLAMI | D3: ORT.K.BAŞI FİYAT | E3: =E2/C3 -> #DIV/0! | L3: SATIŞ FİYATI
A4: TUZ BİBER BİLET
A5: İTİCKET
A6: PASSO BİLET
A7: BİLETİNİ AL | L7: 150
A8: BİLETİNO MÜŞTERİ SAYISI
A9: BİLETİX MÜŞTERİ SAYISI
A10: BU BİLET MÜŞTERİ SAYISI
A11: CARİ HESAP
A12: SALON SATIŞ KİŞİ SAYISI | C12: =C3-C4-C5-C6-C7-C8-C9-C10-C11 -> 0 | D12: =SUM(D13:E16) -> 0
A13: OTOPARK GELİRİ NAKİT
A14: OTOPARK GELİRİ KREDİ KARTI
A15: GÜNLÜK NAKİT
A16: GÜNLÜK KREDİ KARTI
A17: NAKİT VE KREDİ KARTI TOPLAMI
A19: GÜNLÜK KASADAN HARCAMALAR TOPLAMI | D19: =SUM(D21:E33) -> 0
A20: KASA NAKİT HARCAMA DETAYI | B20: AÇIKLAMA | D20: TUTAR
K32: =D32/1.18 -> 0
A34: YÖNETİME TESLİM EDİLMESİ GEREKEN NAKİT TUTAR | D34: =D15+D13-D19 -> 0
A35: KASA TESLİMATI AÇIKLAMASI
A36: KASA AÇILIŞI TUTARI | B36: YÖNETİMDEN GELEN TUTAR | C36: KASA ÇIKIŞI | D36: KASADA OLMASI GEREKEN TUTAR | E36: REEL KASA MEVCUDU | F36: ANA KASA KAPANIŞ FARKI
A37: ='9'!E37 -> 3818.48 | C37: =D19 -> 0 | D37: =A37+B37+D15-C37 -> 3818.48 | E37: =D37 -> 3818.48 | F37: =E37-D37 -> 0
A38: CARİ AÇIKLAMASI | B38: DEVİR BAKİYESİ | C38: YENİ ALIM | D38: ÖDEME | E38: SON BAKİYESİ
A39: NURETTİN ATILMIŞ CARİSİ | B39: ='9'!E39 -> 928120 | E39: =B39+C39-D39 -> 928120
A40: DAVUL ÜCRETİ CARİSİ | B40: ='9'!E40 -> 0 | E40: =B40+C40-D40 -> 0
A41: ÖDENMEZ İKRAM TOPLAMI | E41: =SUM(E43:E68) -> 0
A42: ÖDENMEZ İKRAMI KULLANAN ADI SAYADI | B42: ÇEK NO | C42: ÇEKİN İÇERİĞİ (ÜRÜN DETAYI | E42: ÖDENMEZİN TOPLAM TUTARI
A70: İŞLETME GİDERLERİ DETAYI | B70: TUTAR
A71: SANATÇI GİDERİ
A72: TEKNİK EKİPMAN GİDERLERİ
A73: MATMAZEL COCO
A74: YEMEK GİDERİ BIRLIK GIDA 82 SET MENÜ
A75: İÇECEK KDV Sİ | B75: =B77*0.1568 -> 0
A76: %10 SERVİS ÜCRETİ ÖDENECEK TUTAR
A77: İÇECEK SATIŞ VE ÖDENMEZ MALİYETİ
A78: =A19 -> GÜNLÜK KASADAN HARCAMALAR TOPLAMI | B78: =D19 -> 0
A79: PERSONEL YEMEK 55 ADET
A81: İŞLETME GİDERLERİ | B81: =SUM(B71:B80) -> 0 | C81: =E2-B81 -> 0 | H81: Gn. Toplam | I81: =SUM(I3:I77) -> 0
...

Sheet 11
A1: ='10'!A1+1 -> 46184 | B1: ='[4]1'!B1:E1 -> DADA SALON GÜN SONU RAPORU
C2: GÜNLÜK TOPLAM CİRO | E2: =D4+D5+D6+D7+D8+D9+D10+D11+D12 -> 0 | G2: ÜRÜN DETAYI | H2: ÖDENMEZ İKRAMI KULLANAN ADI SAYADI | I2: ÖDENMEZİN TOPLAM TUTARI
A3: KUVER SAYISI TOPLAMI | D3: ORT.K.BAŞI FİYAT | E3: =E2/C3 -> #DIV/0! | L3: SATIŞ FİYATI
A4: TUZ BİBER BİLET
A5: İTİCKET
A6: PASSO BİLET
A7: BİLETİNİ AL | L7: 150
A8: BİLETİNO MÜŞTERİ SAYISI
A9: BİLETİX MÜŞTERİ SAYISI
A10: BU BİLET MÜŞTERİ SAYISI
A11: CARİ HESAP
A12: SALON SATIŞ KİŞİ SAYISI | C12: =C3-C4-C5-C6-C7-C8-C9-C10-C11 -> 0 | D12: =SUM(D13:E16) -> 0
A13: OTOPARK GELİRİ NAKİT
A14: OTOPARK GELİRİ KREDİ KARTI
A15: GÜNLÜK NAKİT
A16: GÜNLÜK KREDİ KARTI
A17: NAKİT VE KREDİ KARTI TOPLAMI
A19: GÜNLÜK KASADAN HARCAMALAR TOPLAMI | D19: =SUM(D21:E33) -> 0
A20: KASA NAKİT HARCAMA DETAYI | B20: AÇIKLAMA | D20: TUTAR
A34: YÖNETİME TESLİM EDİLMESİ GEREKEN NAKİT TUTAR | D34: =D15+D13-D19 -> 0
A35: KASA TESLİMATI AÇIKLAMASI
A36: KASA AÇILIŞI TUTARI | B36: YÖNETİMDEN GELEN TUTAR | C36: KASA ÇIKIŞI | D36: KASADA OLMASI GEREKEN TUTAR | E36: REEL KASA MEVCUDU | F36: ANA KASA KAPANIŞ FARKI
A37: ='10'!E37 -> 3818.48 | C37: =D19 -> 0 | D37: =A37+B37+D15-C37 -> 3818.48 | E37: =D37 -> 3818.48 | F37: =E37-D37 -> 0
A38: CARİ AÇIKLAMASI | B38: DEVİR BAKİYESİ | C38: YENİ ALIM | D38: ÖDEME | E38: SON BAKİYESİ
A39: NURETTİN ATILMIŞ CARİSİ | B39: ='10'!E39 -> 928120 | E39: =B39+C39-D39 -> 928120
A40: DAVUL ÜCRETİ CARİSİ | B40: ='10'!E40 -> 0 | E40: =B40+C40-D40 -> 0
A41: ÖDENMEZ İKRAM TOPLAMI | E41: =SUM(E43:E68) -> 0
A42: ÖDENMEZ İKRAMI KULLANAN ADI SAYADI | B42: ÇEK NO | C42: ÇEKİN İÇERİĞİ (ÜRÜN DETAYI | E42: ÖDENMEZİN TOPLAM TUTARI
A70: İŞLETME GİDERLERİ DETAYI | B70: TUTAR
A71: SANATÇI GİDERİ
A72: TEKNİK EKİPMAN GİDERLERİ
A73: MATMAZEL COCO
A74: YEMEK GİDERİ BİRLİK GIDA 140 ADET SET MENÜ ( 960 TL DEN)
A75: İÇECEK KDV Sİ | B75: =B77*0.1568 -> 0
A76: %10 SERVİS ÜCRETİ ÖDENECEK TUTAR
A77: İÇECEK SATIŞ VE ÖDENMEZ MALİYETİ
A78: =A19 -> GÜNLÜK KASADAN HARCAMALAR TOPLAMI | B78: =D19 -> 0
A79: PERSONEL YEMEK 55 ADET
A81: İŞLETME GİDERLERİ | B81: =SUM(B71:B80) -> 0 | C81: =E2-B81 -> 0 | H81: Gn. Toplam | I81: =SUM(I3:I77) -> 0
H82: FARK | I82: =I81-E41 -> 0
...

Sheet 12
A1: ='11'!A1+1 -> 46185 | B1: ='[5]1'!B1:E1 -> DADA SALON GÜN SONU RAPORU
C2: GÜNLÜK TOPLAM CİRO | E2: =D4+D5+D6+D7+D8+D9+D10+D11+D12 -> 0 | G2: ÜRÜN DETAYI | H2: ÖDENMEZ İKRAMI KULLANAN ADI SAYADI | I2: ÖDENMEZİN TOPLAM TUTARI
A3: KUVER SAYISI TOPLAMI | D3: ORT.K.BAŞI FİYAT | E3: =E2/C3 -> #DIV/0! | L3: SATIŞ FİYATI
A4: TUZ BİBER BİLET
A5: İTİCKET
A6: PASSO BİLET
A7: BİLETİNİ AL | L7: 150
A8: BİLETİNO MÜŞTERİ SAYISI
A9: BİLETİX MÜŞTERİ SAYISI
A10: BU BİLET MÜŞTERİ SAYISI
A11: CARİ HESAP
A12: SALON SATIŞ KİŞİ SAYISI | C12: =C3-C4-C5-C6-C7-C8-C9-C10-C11 -> 0 | D12: =SUM(D13:E16) -> 0
A13: OTOPARK GELİRİ NAKİT
A14: OTOPARK GELİRİ KREDİ KARTI
A15: GÜNLÜK NAKİT
A16: GÜNLÜK KREDİ KARTI
A17: NAKİT VE KREDİ KARTI TOPLAMI
A19: GÜNLÜK KASADAN HARCAMALAR TOPLAMI | D19: =SUM(D21:E33) -> 0
A20: KASA NAKİT HARCAMA DETAYI | B20: AÇIKLAMA | D20: TUTAR
A34: YÖNETİME TESLİM EDİLMESİ GEREKEN NAKİT TUTAR | D34: =D15+D13-D19 -> 0
A35: KASA TESLİMATI AÇIKLAMASI
A36: KASA AÇILIŞI TUTARI | B36: YÖNETİMDEN GELEN TUTAR | C36: KASA ÇIKIŞI | D36: KASADA OLMASI GEREKEN TUTAR | E36: REEL KASA MEVCUDU | F36: ANA KASA KAPANIŞ FARKI
A37: ='11'!E37 -> 3818.48 | C37: =D19 -> 0 | D37: =A37+B37+D15-C37 -> 3818.48 | E37: =D37 -> 3818.48 | F37: =E37-D37 -> 0
A38: CARİ AÇIKLAMASI | B38: DEVİR BAKİYESİ | C38: YENİ ALIM | D38: ÖDEME | E38: SON BAKİYESİ
A39: NURETTİN ATILMIŞ CARİSİ | B39: ='11'!E39 -> 928120 | E39: =B39+C39-D39 -> 928120
A40: DAVUL ÜCRETİ CARİSİ | B40: ='11'!E40 -> 0 | E40: =B40+C40-D40 -> 0
A41: ÖDENMEZ İKRAM TOPLAMI | E41: =SUM(E43:E68) -> 0
A42: ÖDENMEZ İKRAMI KULLANAN ADI SAYADI | B42: ÇEK NO | C42: ÇEKİN İÇERİĞİ (ÜRÜN DETAYI | E42: ÖDENMEZİN TOPLAM TUTARI
A70: İŞLETME GİDERLERİ DETAYI | B70: TUTAR
A71: SANATÇI GİDERİ
A72: TEKNİK EKİPMAN GİDERLERİ
A73: MATMAZEL COCO
A74: YEMEK GİDERİ 225 FİNGERFOOD HOME STYLE.
A75: İÇECEK KDV Sİ | B75: =B77*0.1568 -> 0
A76: %10 SERVİS ÜCRETİ ÖDENECEK TUTAR
A77: İÇECEK SATIŞ VE ÖDENMEZ MALİYETİ
A78: =A19 -> GÜNLÜK KASADAN HARCAMALAR TOPLAMI | B78: =D19 -> 0
A79: PERSONEL YEMEK 35 ADET
A81: İŞLETME GİDERLERİ | B81: =SUM(B71:B80) -> 0 | C81: =E2-B81 -> 0 | H81: Gn. Toplam | I81: =SUM(I3:I77) -> 0
H82: FARK | I82: =I81-E41 -> 0
...

Sheet 13
A1: ='12'!A1+1 -> 46186 | B1: ='[6]1'!B1:E1 -> DADA SALON GÜN SONU RAPORU
C2: GÜNLÜK TOPLAM CİRO | E2: =D4+D5+D6+D7+D8+D9+D10+D11+D12 -> 0 | G2: ÜRÜN DETAYI | H2: ÖDENMEZ İKRAMI KULLANAN ADI SAYADI | I2: ÖDENMEZİN TOPLAM TUTARI
A3: KUVER SAYISI TOPLAMI | D3: ORT.K.BAŞI FİYAT | E3: =E2/C3 -> #DIV/0! | L3: SATIŞ FİYATI
A4: TUZ BİBER BİLET
A5: İTİCKET
A6: PASSO BİLET
A7: BİLETİNİ AL | L7: 150
A8: BİLETİNO MÜŞTERİ SAYISI
A9: BİLETİX MÜŞTERİ SAYISI
A10: BU BİLET MÜŞTERİ SAYISI
A11: CARİ HESAP
A12: SALON SATIŞ KİŞİ SAYISI | C12: =C3-C4-C5-C6-C7-C8-C9-C10-C11 -> 0 | D12: =SUM(D13:E16) -> 0
A13: OTOPARK GELİRİ NAKİT
A14: OTOPARK GELİRİ KREDİ KARTI
A15: GÜNLÜK NAKİT
A16: GÜNLÜK KREDİ KARTI
A17: NAKİT VE KREDİ KARTI TOPLAMI
A19: GÜNLÜK KASADAN HARCAMALAR TOPLAMI | D19: =SUM(D21:E33) -> 0 | K19: =6200*1.18 -> 7316
A20: KASA NAKİT HARCAMA DETAYI | B20: AÇIKLAMA | D20: TUTAR
A34: YÖNETİME TESLİM EDİLMESİ GEREKEN NAKİT TUTAR | D34: =D15+D13-D19 -> 0
A35: KASA TESLİMATI AÇIKLAMASI
A36: KASA AÇILIŞI TUTARI | B36: YÖNETİMDEN GELEN TUTAR | C36: KASA ÇIKIŞI | D36: KASADA OLMASI GEREKEN TUTAR | E36: REEL KASA MEVCUDU | F36: ANA KASA KAPANIŞ FARKI
A37: ='12'!E37 -> 3818.48 | C37: =D19 -> 0 | D37: =A37+B37+D15-C37 -> 3818.48 | E37: =D37 -> 3818.48 | F37: =E37-D37 -> 0
A38: CARİ AÇIKLAMASI | B38: DEVİR BAKİYESİ | C38: YENİ ALIM | D38: ÖDEME | E38: SON BAKİYESİ
A39: NURETTİN ATILMIŞ CARİSİ | B39: ='12'!E39 -> 928120 | E39: =B39+C39-D39 -> 928120
A40: DAVUL ÜCRETİ CARİSİ | B40: ='12'!E40 -> 0 | E40: =B40+C40-D40 -> 0
A41: ÖDENMEZ İKRAM TOPLAMI | E41: =SUM(E43:E68) -> 0
A42: ÖDENMEZ İKRAMI KULLANAN ADI SAYADI | B42: ÇEK NO | C42: ÇEKİN İÇERİĞİ (ÜRÜN DETAYI | E42: ÖDENMEZİN TOPLAM TUTARI
A70: İŞLETME GİDERLERİ DETAYI | B70: TUTAR
A71: SANATÇI GİDERİ
A72: TEKNİK EKİPMAN GİDERLERİ
A73: MATMAZEL COCO
A74: YEMEK GİDERİ HOME STYLE 200 SET MENÜ ( 1,445 TL KDV DAHIL KISI BASI)
A75: İÇECEK KDV Sİ | B75: =B77*0.1568 -> 0
A76: %10 SERVİS ÜCRETİ ÖDENECEK TUTAR
A77: İÇECEK SATIŞ VE ÖDENMEZ MALİYETİ
A78: =A19 -> GÜNLÜK KASADAN HARCAMALAR TOPLAMI | B78: =D19 -> 0
A79: PERSONEL YEMEK 55 ADET
A81: İŞLETME GİDERLERİ | B81: =SUM(B71:B80) -> 0 | C81: =E2-B81 -> 0 | H81: Gn. Toplam | I81: =SUM(I3:I77) -> 0
H82: FARK | I82: =I81-E41 -> 0
...

Sheet 14
A1: ='13'!A1+1 -> 46187 | B1: ='1'!B1:E1 -> DADA SALON KABARETT GÜN SONU RAPORU
C2: GÜNLÜK TOPLAM CİRO | E2: =D4+D5+D6+D7+D8+D9+D10+D11+D12 -> 0 | G2: ÜRÜN DETAYI | H2: ÖDENMEZ İKRAMI KULLANAN ADI SAYADI | I2: ÖDENMEZİN TOPLAM TUTARI
A3: KUVER SAYISI TOPLAMI | D3: ORT.K.BAŞI FİYAT | E3: =E2/C3 -> #DIV/0! | L3: SATIŞ FİYATI
A4: TUZ BİBER BİLET
A5: İTİCKET
A6: PASSO BİLET
A7: BİLETİNİ AL | L7: 150
A8: BİLETİNO MÜŞTERİ SAYISI
A9: BİLETİX MÜŞTERİ SAYISI
A10: BU BİLET MÜŞTERİ SAYISI
A11: CARİ HESAP
A12: SALON SATIŞ KİŞİ SAYISI | C12: =C3-C4-C5-C6-C7-C8-C9-C10-C11 -> 0 | D12: =SUM(D13:E16) -> 0
A13: OTOPARK GELİRİ NAKİT
A14: OTOPARK GELİRİ KREDİ KARTI
A15: GÜNLÜK NAKİT
A16: GÜNLÜK KREDİ KARTI
A17: NAKİT VE KREDİ KARTI TOPLAMI
A19: GÜNLÜK KASADAN HARCAMALAR TOPLAMI | D19: =SUM(D21:E33) -> 0
A20: KASA NAKİT HARCAMA DETAYI | B20: AÇIKLAMA | D20: TUTAR
A34: YÖNETİME TESLİM EDİLMESİ GEREKEN NAKİT TUTAR | D34: =D15+D13-D19 -> 0
A35: KASA TESLİMATI AÇIKLAMASI
A36: KASA AÇILIŞI TUTARI | B36: YÖNETİMDEN GELEN TUTAR | C36: KASA ÇIKIŞI | D36: KASADA OLMASI GEREKEN TUTAR | E36: REEL KASA MEVCUDU | F36: ANA KASA KAPANIŞ FARKI
A37: ='13'!E37 -> 3818.48 | C37: =D19 -> 0 | D37: =A37+B37+D15-C37 -> 3818.48 | E37: =D37 -> 3818.48 | F37: =E37-D37 -> 0
A38: CARİ AÇIKLAMASI | B38: DEVİR BAKİYESİ | C38: YENİ ALIM | D38: ÖDEME | E38: SON BAKİYESİ
A39: NURETTİN ATILMIŞ CARİSİ | B39: ='13'!E39 -> 928120 | E39: =B39+C39-D39 -> 928120
A40: DAVUL ÜCRETİ CARİSİ | B40: ='13'!E40 -> 0 | E40: =B40+C40-D40 -> 0
A41: ÖDENMEZ İKRAM TOPLAMI | E41: =SUM(E43:E68) -> 0
A42: ÖDENMEZ İKRAMI KULLANAN ADI SAYADI | B42: ÇEK NO | C42: ÇEKİN İÇERİĞİ (ÜRÜN DETAYI | E42: ÖDENMEZİN TOPLAM TUTARI
A70: İŞLETME GİDERLERİ DETAYI | B70: TUTAR
A71: SANATÇI GİDERİ MİRKELAM + FEHMİ
A72: TEKNİK EKİPMAN GİDERLERİ
A73: MATMAZEL COCO
A74: YEMEK GİDERİ HOME STYLE 250 FINGERFOOD MENÜ ( KİŞİ BAŞI : 1.155 TL KDV DAHİL )
A75: İÇECEK KDV Sİ | B75: =B77*0.1568 -> 0
A76: %10 SERVİS ÜCRETİ ÖDENECEK TUTAR
A77: İÇECEK SATIŞ VE ÖDENMEZ MALİYETİ
A78: =A19 -> GÜNLÜK KASADAN HARCAMALAR TOPLAMI | B78: =D19 -> 0
A79: PERSONEL YEMEK 55 ADET
A81: İŞLETME GİDERLERİ | B81: =SUM(B71:B80) -> 0 | C81: =E2-B81 -> 0 | H81: Gn. Toplam | I81: =SUM(I3:I77) -> 0
H82: FARK | I82: =I81-E41 -> 0
...

Sheet 15
A1: ='14'!A1+1 -> 46188 | B1: ='[7]1'!B1:E1 -> DADA SALON GÜN SONU RAPORU
C2: GÜNLÜK TOPLAM CİRO | E2: =D4+D5+D6+D7+D8+D9+D10+D11+D12 -> 0 | G2: ÜRÜN DETAYI | H2: ÖDENMEZ İKRAMI KULLANAN ADI SAYADI | I2: ÖDENMEZİN TOPLAM TUTARI
A3: KUVER SAYISI TOPLAMI | D3: ORT.K.BAŞI FİYAT | E3: =E2/C3 -> #DIV/0! | L3: SATIŞ FİYATI
A4: TUZ BİBER BİLET
A5: İTİCKET
A6: PASSO BİLET
A7: BİLETİNİ AL | L7: 150
A8: BİLETİNO MÜŞTERİ SAYISI
A9: BİLETİX MÜŞTERİ SAYISI
A10: BU BİLET MÜŞTERİ SAYISI
A11: CARİ HESAP
A12: SALON SATIŞ KİŞİ SAYISI | C12: =C3-C4-C5-C6-C7-C8-C9-C10-C11 -> 0 | D12: =SUM(D13:E16) -> 0
A13: OTOPARK GELİRİ NAKİT
A14: OTOPARK GELİRİ KREDİ KARTI
A15: GÜNLÜK NAKİT
A16: GÜNLÜK KREDİ KARTI
A17: NAKİT VE KREDİ KARTI TOPLAMI
A19: GÜNLÜK KASADAN HARCAMALAR TOPLAMI | D19: =SUM(D21:E33) -> 0
A20: KASA NAKİT HARCAMA DETAYI | B20: AÇIKLAMA | D20: TUTAR
A34: YÖNETİME TESLİM EDİLMESİ GEREKEN NAKİT TUTAR | D34: =D15+D13-D19 -> 0
A35: KASA TESLİMATI AÇIKLAMASI
A36: KASA AÇILIŞI TUTARI | B36: YÖNETİMDEN GELEN TUTAR | C36: KASA ÇIKIŞI | D36: KASADA OLMASI GEREKEN TUTAR | E36: REEL KASA MEVCUDU | F36: ANA KASA KAPANIŞ FARKI
A37: ='14'!E37 -> 3818.48 | C37: =D19 -> 0 | D37: =A37+B37+D15-C37 -> 3818.48 | E37: =D37 -> 3818.48 | F37: =E37-D37 -> 0
A38: CARİ AÇIKLAMASI | B38: DEVİR BAKİYESİ | C38: YENİ ALIM | D38: ÖDEME | E38: SON BAKİYESİ
A39: NURETTİN ATILMIŞ CARİSİ | B39: ='14'!E39 -> 928120 | E39: =B39+C39-D39 -> 928120
A40: DAVUL ÜCRETİ CARİSİ | B40: ='14'!E40 -> 0 | E40: =B40+C40-D40 -> 0
A41: ÖDENMEZ İKRAM TOPLAMI | E41: =SUM(E43:E68) -> 0
A42: ÖDENMEZ İKRAMI KULLANAN ADI SAYADI | B42: ÇEK NO | C42: ÇEKİN İÇERİĞİ (ÜRÜN DETAYI | E42: ÖDENMEZİN TOPLAM TUTARI
A70: İŞLETME GİDERLERİ DETAYI | B70: TUTAR
A71: SANATÇI GİDERİ
A72: TEKNİK EKİPMAN GİDERLERİ
A73: MATMAZEL COCO
A74: YEMEK GİDERİ BIRLIK GIDA 105 SET MENÜ+ 2 ORDORV TABAĞI
A75: İÇECEK KDV Sİ | B75: =B77*0.1568 -> 0
A76: %10 SERVİS ÜCRETİ ÖDENECEK TUTAR
A77: İÇECEK SATIŞ VE ÖDENMEZ MALİYETİ
A78: =A19 -> GÜNLÜK KASADAN HARCAMALAR TOPLAMI | B78: =D19 -> 0
A79: PERSONEL YEMEK 35 ADET
A81: İŞLETME GİDERLERİ | B81: =SUM(B71:B80) -> 0 | C81: =E2-B81 -> 0 | H81: Gn. Toplam | I81: =SUM(I3:I77) -> 0
H82: FARK | I82: =I81-E41 -> 0
...

Sheet 16
A1: ='15'!A1+1 -> 46189 | B1: ='[8]1'!B1:E1 -> DADA SALON GÜN SONU RAPORU
C2: GÜNLÜK TOPLAM CİRO | E2: =D4+D5+D6+D7+D8+D9+D10+D11+D12 -> 0 | G2: ÜRÜN DETAYI | H2: ÖDENMEZ İKRAMI KULLANAN ADI SAYADI | I2: ÖDENMEZİN TOPLAM TUTARI
A3: KUVER SAYISI TOPLAMI | D3: ORT.K.BAŞI FİYAT | E3: =E2/C3 -> #DIV/0! | L3: SATIŞ FİYATI
A4: TUZ BİBER BİLET
A5: İTİCKET
A6: PASSO BİLET
A7: BİLETİNİ AL | L7: 150
A8: BİLETİNO MÜŞTERİ SAYISI
A9: BİLETİX MÜŞTERİ SAYISI
A10: BU BİLET MÜŞTERİ SAYISI
A11: CARİ HESAP
A12: SALON SATIŞ KİŞİ SAYISI | C12: =C3-C4-C5-C6-C7-C8-C9-C10-C11 -> 0 | D12: =SUM(D13:E16) -> 0
A13: OTOPARK GELİRİ NAKİT
A14: OTOPARK GELİRİ KREDİ KARTI
A15: GÜNLÜK NAKİT
A16: GÜNLÜK KREDİ KARTI
A17: NAKİT VE KREDİ KARTI TOPLAMI
A19: GÜNLÜK KASADAN HARCAMALAR TOPLAMI | D19: =SUM(D21:E33) -> 0
A20: KASA NAKİT HARCAMA DETAYI | B20: AÇIKLAMA | D20: TUTAR
A34: YÖNETİME TESLİM EDİLMESİ GEREKEN NAKİT TUTAR | D34: =D15+D13-D19 -> 0
A35: KASA TESLİMATI AÇIKLAMASI
A36: KASA AÇILIŞI TUTARI | B36: YÖNETİMDEN GELEN TUTAR | C36: KASA ÇIKIŞI | D36: KASADA OLMASI GEREKEN TUTAR | E36: REEL KASA MEVCUDU | F36: ANA KASA KAPANIŞ FARKI
A37: ='15'!E37 -> 3818.48 | C37: =D19 -> 0 | D37: =A37+B37+D15-C37 -> 3818.48 | E37: =D37 -> 3818.48 | F37: =E37-D37 -> 0
A38: CARİ AÇIKLAMASI | B38: DEVİR BAKİYESİ | C38: YENİ ALIM | D38: ÖDEME | E38: SON BAKİYESİ
A39: NURETTİN ATILMIŞ CARİSİ | B39: ='15'!E39 -> 928120 | E39: =B39+C39-D39 -> 928120
A40: DAVUL ÜCRETİ CARİSİ | B40: ='15'!E40 -> 0 | E40: =B40+C40-D40 -> 0
A41: ÖDENMEZ İKRAM TOPLAMI | E41: =SUM(E43:E68) -> 0
A42: ÖDENMEZ İKRAMI KULLANAN ADI SAYADI | B42: ÇEK NO | C42: ÇEKİN İÇERİĞİ (ÜRÜN DETAYI | E42: ÖDENMEZİN TOPLAM TUTARI
A70: İŞLETME GİDERLERİ DETAYI | B70: TUTAR
A71: SANATÇI GİDERİ
A72: TEKNİK EKİPMAN GİDERLERİ
A73: MATMAZEL COCO
A74: YEMEK GİDERİ BIRLIK GIDA 162 SET MENU
A75: İÇECEK KDV Sİ | B75: =B77*0.1568 -> 0
A76: %10 SERVİS ÜCRETİ ÖDENECEK TUTAR
A77: İÇECEK SATIŞ VE ÖDENMEZ MALİYETİ
A78: =A19 -> GÜNLÜK KASADAN HARCAMALAR TOPLAMI | B78: =D19 -> 0
A79: PERSONEL YEMEK 35 ADET
A81: İŞLETME GİDERLERİ | B81: =SUM(B71:B80) -> 0 | C81: =E2-B81 -> 0 | H81: Gn. Toplam | I81: =SUM(I3:I77) -> 0
H82: FARK | I82: =I81-E41 -> 0
...

Sheet 17
A1: ='16'!A1+1 -> 46190 | B1: ='[9]1'!B1:E1 -> DADA SALON KABARETT GÜN SONU RAPORU
C2: GÜNLÜK TOPLAM CİRO | E2: =D4+D5+D6+D7+D8+D9+D10+D11+D12 -> 0 | G2: ÜRÜN DETAYI | H2: ÖDENMEZ İKRAMI KULLANAN ADI SAYADI | I2: ÖDENMEZİN TOPLAM TUTARI
A3: KUVER SAYISI TOPLAMI | D3: ORT.K.BAŞI FİYAT | E3: =E2/C3 -> #DIV/0! | L3: SATIŞ FİYATI
A4: TUZ BİBER BİLET
A5: İTİCKET
A6: PASSO BİLET
A7: BİLETİNİ AL | L7: 150
A8: BİLETİNO MÜŞTERİ SAYISI
A9: BİLETİX MÜŞTERİ SAYISI
A10: BU BİLET MÜŞTERİ SAYISI
A11: CARİ HESAP
A12: SALON SATIŞ KİŞİ SAYISI | C12: =C3-C11 -> 0 | D12: =SUM(D13:E16) -> 0
A13: OTOPARK GELİRİ NAKİT
A14: OTOPARK GELİRİ KREDİ KARTI
A15: GÜNLÜK NAKİT
A16: GÜNLÜK KREDİ KARTI
A17: NAKİT VE KREDİ KARTI TOPLAMI
A19: GÜNLÜK KASADAN HARCAMALAR TOPLAMI | D19: =SUM(D21:E33) -> 0
A20: KASA NAKİT HARCAMA DETAYI | B20: AÇIKLAMA | D20: TUTAR
A34: YÖNETİME TESLİM EDİLMESİ GEREKEN NAKİT TUTAR | D34: =D15+D13-D19 -> 0
A35: KASA TESLİMATI AÇIKLAMASI
A36: KASA AÇILIŞI TUTARI | B36: YÖNETİMDEN GELEN TUTAR | C36: KASA ÇIKIŞI | D36: KASADA OLMASI GEREKEN TUTAR | E36: REEL KASA MEVCUDU | F36: ANA KASA KAPANIŞ FARKI
A37: ='16'!E37 -> 3818.48 | C37: =D19 -> 0 | D37: =A37+B37+D15-C37 -> 3818.48 | E37: =D37 -> 3818.48 | F37: =E37-D37 -> 0
A38: CARİ AÇIKLAMASI | B38: DEVİR BAKİYESİ | C38: YENİ ALIM | D38: ÖDEME | E38: SON BAKİYESİ
A39: NURETTİN ATILMIŞ CARİSİ | B39: ='16'!E39 -> 928120 | E39: =B39+C39-D39 -> 928120
A40: DAVUL ÜCRETİ CARİSİ | B40: ='16'!E40 -> 0 | E40: =B40+C40-D40 -> 0
A41: ÖDENMEZ İKRAM TOPLAMI | E41: =SUM(E43:E68) -> 0
A42: ÖDENMEZ İKRAMI KULLANAN ADI SAYADI | B42: ÇEK NO | C42: ÇEKİN İÇERİĞİ (ÜRÜN DETAYI | E42: ÖDENMEZİN TOPLAM TUTARI
A70: İŞLETME GİDERLERİ DETAYI | B70: TUTAR
A71: SANATÇI GİDERİ
A72: TEKNİK EKİPMAN GİDERLERİ
A73: MATMAZEL COCO
A74: YEMEK GİDERİ UMAMİ YEMEK 300 KİŞİ FİNGERFOOD (KİŞİ BAŞI 770 TL KDV DAHIL,AYRICA EXTRA 300 KISILIK TON BALIKLI WREPP FATURA EDILICEK TARAFIMIZA)
A75: İÇECEK KDV Sİ | B75: =B77*0.1568 -> 0
A76: %10 SERVİS ÜCRETİ ÖDENECEK TUTAR
A77: İÇECEK SATIŞ VE ÖDENMEZ MALİYETİ | C77: =B77/C3 -> #DIV/0!
A78: =A19 -> GÜNLÜK KASADAN HARCAMALAR TOPLAMI | B78: =D19 -> 0
A79: PERSONEL YEMEK 35 ADET
A81: İŞLETME GİDERLERİ | B81: =SUM(B71:B80) -> 0 | C81: =E2-B81 -> 0 | H81: Gn. Toplam | I81: =SUM(I3:I77) -> 0
H82: FARK | I82: =I81-E41 -> 0
...

Sheet 18
A1: ='17'!A1+1 -> 46191 | B1: ='[10]1'!B1:E1 -> DADA SALON KABARETT GÜN SONU RAPORU
C2: GÜNLÜK TOPLAM CİRO | E2: =D4+D5+D6+D7+D8+D9+D10+D11+D12 -> 0 | G2: ÜRÜN DETAYI | H2: ÖDENMEZ İKRAMI KULLANAN ADI SAYADI | I2: ÖDENMEZİN TOPLAM TUTARI
A3: KUVER SAYISI TOPLAMI | D3: ORT.K.BAŞI FİYAT | E3: =E2/C3 -> #DIV/0! | L3: SATIŞ FİYATI
A4: TUZ BİBER BİLET
A5: İTİCKET
A6: PASSO BİLET
A7: BİLETİNİ AL | L7: 150
A8: BİLETİNO MÜŞTERİ SAYISI
A9: BİLETİX MÜŞTERİ SAYISI
A10: BU BİLET MÜŞTERİ SAYISI
A11: CARİ HESAP
A12: SALON SATIŞ KİŞİ SAYISI | C12: =C3-C4-C5-C6-C7-C8-C9-C10-C11 -> 0 | D12: =SUM(D13:E16) -> 0
A13: OTOPARK GELİRİ NAKİT
A14: OTOPARK GELİRİ KREDİ KARTI
A15: GÜNLÜK NAKİT
A16: GÜNLÜK KREDİ KARTI
A17: NAKİT VE KREDİ KARTI TOPLAMI
A19: GÜNLÜK KASADAN HARCAMALAR TOPLAMI | D19: =SUM(D21:E33) -> 0
A20: KASA NAKİT HARCAMA DETAYI | B20: AÇIKLAMA | D20: TUTAR
A34: YÖNETİME TESLİM EDİLMESİ GEREKEN NAKİT TUTAR | D34: =D15+D13-D19 -> 0
A35: KASA TESLİMATI AÇIKLAMASI
A36: KASA AÇILIŞI TUTARI | B36: YÖNETİMDEN GELEN TUTAR | C36: KASA ÇIKIŞI | D36: KASADA OLMASI GEREKEN TUTAR | E36: REEL KASA MEVCUDU | F36: ANA KASA KAPANIŞ FARKI
A37: ='17'!E37 -> 3818.48 | C37: =D19 -> 0 | D37: =A37+B37+D15-C37 -> 3818.48 | E37: =D37 -> 3818.48 | F37: =E37-D37 -> 0
A38: CARİ AÇIKLAMASI | B38: DEVİR BAKİYESİ | C38: YENİ ALIM | D38: ÖDEME | E38: SON BAKİYESİ
A39: NURETTİN ATILMIŞ CARİSİ | B39: ='17'!E39 -> 928120 | E39: =B39+C39-D39 -> 928120
A40: DAVUL ÜCRETİ CARİSİ | B40: ='17'!E40 -> 0 | E40: =B40+C40-D40 -> 0
A41: ÖDENMEZ İKRAM TOPLAMI | E41: =SUM(E43:E68) -> 0
A42: ÖDENMEZ İKRAMI KULLANAN ADI SAYADI | B42: ÇEK NO | C42: ÇEKİN İÇERİĞİ (ÜRÜN DETAYI | E42: ÖDENMEZİN TOPLAM TUTARI
A70: İŞLETME GİDERLERİ DETAYI | B70: TUTAR
A71: SANATÇI GİDERİ
A72: TEKNİK EKİPMAN GİDERLERİ
A73: MATMAZEL COCO
A74: YEMEK GİDERİ BİRLİK GIDA 152 SET MENÜ + 4 DILIM PEYNIR +2 TABAK ORDORV
A75: İÇECEK KDV Sİ | B75: =B77*0.1568 -> 0
A76: %10 SERVİS ÜCRETİ ÖDENECEK TUTAR
A77: İÇECEK SATIŞ VE ÖDENMEZ MALİYETİ | C77: =B77/C3 -> #DIV/0!
A78: =A19 -> GÜNLÜK KASADAN HARCAMALAR TOPLAMI | B78: =D19 -> 0
A79: PERSONEL YEMEK 55 ADET
A81: İŞLETME GİDERLERİ | B81: =SUM(B71:B80) -> 0 | C81: =E2-B81 -> 0 | H81: Gn. Toplam | I81: =SUM(I3:I77) -> 0
H82: FARK | I82: =I81-E41 -> 0
...

Sheet 19
A1: ='18'!A1+1 -> 46192 | B1: ='1'!B1:E1 -> DADA SALON KABARETT GÜN SONU RAPORU
C2: GÜNLÜK TOPLAM CİRO | E2: =D4+D5+D6+D7+D8+D9+D10+D11+D12 -> 0 | G2: ÜRÜN DETAYI | H2: ÖDENMEZ İKRAMI KULLANAN ADI SAYADI | I2: ÖDENMEZİN TOPLAM TUTARI
A3: KUVER SAYISI TOPLAMI | D3: ORT.K.BAŞI FİYAT | E3: =E2/C3 -> #DIV/0! | L3: SATIŞ FİYATI
A4: TUZ BİBER BİLET
A5: İTİCKET
A6: PASSO BİLET
A7: BİLETİNİ AL | L7: 150
A8: BİLETİNO MÜŞTERİ SAYISI
A9: BİLETİX MÜŞTERİ SAYISI
A10: BU BİLET MÜŞTERİ SAYISI
A11: CARİ HESAP
A12: SALON SATIŞ KİŞİ SAYISI | C12: =C3-C4-C5-C6-C7-C8-C9-C10-C11 -> 0 | D12: =SUM(D13:E16) -> 0
A13: OTOPARK GELİRİ NAKİT
A14: OTOPARK GELİRİ KREDİ KARTI
A15: GÜNLÜK NAKİT
A16: GÜNLÜK KREDİ KARTI
A17: NAKİT VE KREDİ KARTI TOPLAMI
A19: GÜNLÜK KASADAN HARCAMALAR TOPLAMI | D19: =SUM(D21:E33) -> 0
A20: KASA NAKİT HARCAMA DETAYI | B20: AÇIKLAMA | D20: TUTAR
A34: YÖNETİME TESLİM EDİLMESİ GEREKEN NAKİT TUTAR | D34: =D15+D13-D19 -> 0
A35: KASA TESLİMATI AÇIKLAMASI
A36: KASA AÇILIŞI TUTARI | B36: YÖNETİMDEN GELEN TUTAR | C36: KASA ÇIKIŞI | D36: KASADA OLMASI GEREKEN TUTAR | E36: REEL KASA MEVCUDU | F36: ANA KASA KAPANIŞ FARKI
A37: ='18'!E37 -> 3818.48 | C37: =D19 -> 0 | D37: =A37+B37+D15-C37 -> 3818.48 | E37: =D37 -> 3818.48 | F37: =E37-D37 -> 0
A38: CARİ AÇIKLAMASI | B38: DEVİR BAKİYESİ | C38: YENİ ALIM | D38: ÖDEME | E38: SON BAKİYESİ
A39: NURETTİN ATILMIŞ CARİSİ | B39: ='18'!E39 -> 928120 | E39: =B39+C39-D39 -> 928120
A40: DAVUL ÜCRETİ CARİSİ | B40: ='18'!E40 -> 0 | E40: =B40+C40-D40 -> 0
A41: ÖDENMEZ İKRAM TOPLAMI | E41: =SUM(E43:E68) -> 0
A42: ÖDENMEZ İKRAMI KULLANAN ADI SAYADI | B42: ÇEK NO | C42: ÇEKİN İÇERİĞİ (ÜRÜN DETAYI | E42: ÖDENMEZİN TOPLAM TUTARI
A70: İŞLETME GİDERLERİ DETAYI | B70: TUTAR
A71: SANATÇI GİDERİ
A72: TEKNİK EKİPMAN GİDERLERİ
A73: MATMAZEL COCO
A74: YEMEK GİDERİ
A75: İÇECEK KDV Sİ | B75: =B77*0.1568 -> 0
A76: %10 SERVİS ÜCRETİ ÖDENECEK TUTAR
A77: İÇECEK SATIŞ VE ÖDENMEZ MALİYETİ
A78: =A19 -> GÜNLÜK KASADAN HARCAMALAR TOPLAMI | B78: =D19 -> 0
A79: PERSONEL YEMEK 40 ADET
A81: İŞLETME GİDERLERİ | B81: =SUM(B71:B80) -> 0 | C81: =E2-B81 -> 0 | H81: Gn. Toplam | I81: =SUM(I3:I77) -> 0
H82: FARK | I82: =I81-E41 -> 0
...

Sheet 20
A1: ='19'!A1+1 -> 46193 | B1: ='1'!B1:E1 -> DADA SALON KABARETT GÜN SONU RAPORU
C2: GÜNLÜK TOPLAM CİRO | E2: =D4+D5+D6+D7+D8+D9+D10+D11+D12 -> 0 | G2: ÜRÜN DETAYI | H2: ÖDENMEZ İKRAMI KULLANAN ADI SAYADI | I2: ÖDENMEZİN TOPLAM TUTARI
A3: KUVER SAYISI TOPLAMI | D3: ORT.K.BAŞI FİYAT | E3: =E2/C3 -> #DIV/0! | L3: SATIŞ FİYATI
A4: TUZ BİBER BİLET
A5: İTİCKET
A6: PASSO BİLET
A7: BİLETİNİ AL | L7: 150
A8: BİLETİNO MÜŞTERİ SAYISI
A9: BİLETİX MÜŞTERİ SAYISI
A10: BU BİLET MÜŞTERİ SAYISI
A11: CARİ HESAP
A12: SALON SATIŞ KİŞİ SAYISI | C12: =C3-C4-C5-C6-C7-C8-C9-C10-C11 -> 0 | D12: =SUM(D13:E16) -> 0
A13: OTOPARK GELİRİ NAKİT
A14: OTOPARK GELİRİ KREDİ KARTI
A15: GÜNLÜK NAKİT
A16: GÜNLÜK KREDİ KARTI
A17: NAKİT VE KREDİ KARTI TOPLAMI
A19: GÜNLÜK KASADAN HARCAMALAR TOPLAMI | D19: =SUM(D21:E33) -> 0
A20: KASA NAKİT HARCAMA DETAYI | B20: AÇIKLAMA | D20: TUTAR
A34: YÖNETİME TESLİM EDİLMESİ GEREKEN NAKİT TUTAR | D34: =D15+D13-D19 -> 0
A35: KASA TESLİMATI AÇIKLAMASI
A36: KASA AÇILIŞI TUTARI | B36: YÖNETİMDEN GELEN TUTAR | C36: KASA ÇIKIŞI | D36: KASADA OLMASI GEREKEN TUTAR | E36: REEL KASA MEVCUDU | F36: ANA KASA KAPANIŞ FARKI
A37: ='19'!E37 -> 3818.48 | C37: =D19 -> 0 | D37: =A37+B37+D15-C37 -> 3818.48 | E37: =D37 -> 3818.48 | F37: =E37-D37 -> 0
A38: CARİ AÇIKLAMASI | B38: DEVİR BAKİYESİ | C38: YENİ ALIM | D38: ÖDEME | E38: SON BAKİYESİ
A39: NURETTİN ATILMIŞ CARİSİ | B39: ='19'!E39 -> 928120 | E39: =B39+C39-D39 -> 928120
A40: DAVUL ÜCRETİ CARİSİ | B40: ='19'!E40 -> 0 | E40: =B40+C40-D40 -> 0
A41: ÖDENMEZ İKRAM TOPLAMI | E41: =SUM(E43:E68) -> 0
A42: ÖDENMEZ İKRAMI KULLANAN ADI SAYADI | B42: ÇEK NO | C42: ÇEKİN İÇERİĞİ (ÜRÜN DETAYI | E42: ÖDENMEZİN TOPLAM TUTARI
A70: İŞLETME GİDERLERİ DETAYI | B70: TUTAR
A71: SANATÇI GİDERİ
A72: TEKNİK EKİPMAN GİDERLERİ
A73: MATMAZEL COCO
A74: YEMEK GİDERİBIRLIK GIDA 235 SET MENÜ
A75: İÇECEK KDV Sİ | B75: =B77*0.1568 -> 0
A76: %10 SERVİS ÜCRETİ ÖDENECEK TUTAR
A77: İÇECEK SATIŞ VE ÖDENMEZ MALİYETİ
A78: =A19 -> GÜNLÜK KASADAN HARCAMALAR TOPLAMI | B78: =D19 -> 0
A79: PERSONEL YEMEK 35 ADET
A81: İŞLETME GİDERLERİ | B81: =SUM(B71:B80) -> 0 | C81: =E2-B81 -> 0 | H81: Gn. Toplam | I81: =SUM(I3:I77) -> 0
H82: FARK | I82: =I81-E41 -> 0
...

Sheet 21
A1: ='20'!A1+1 -> 46194 | B1: DADA TT GÜN SONU RAPORU
C2: GÜNLÜK TOPLAM CİRO | E2: =D4+D5+D6+D7+D8+D9+D10+D11+D12 -> 0 | G2: ÜRÜN DETAYI | H2: ÖDENMEZ İKRAMI KULLANAN ADI SAYADI | I2: ÖDENMEZİN TOPLAM TUTARI
A3: KUVER SAYISI TOPLAMI | D3: ORT.K.BAŞI FİYAT | E3: =E2/C3 -> #DIV/0! | L3: SATIŞ FİYATI
A4: TUZ BİBER BİLET
A5: İTİCKET
A6: PASSO BİLET
A7: BİLETİNİ AL | L7: 150
A8: BİLETİNO MÜŞTERİ SAYISI
A9: BİLETİX MÜŞTERİ SAYISI
A10: BU BİLET MÜŞTERİ SAYISI
A11: CARİ HESAP
A12: SALON SATIŞ KİŞİ SAYISI | C12: =C3-C4-C5-C6-C7-C8-C9-C10-C11 -> 0 | D12: =SUM(D13:E16) -> 0
A13: OTOPARK GELİRİ NAKİT
A14: OTOPARK GELİRİ KREDİ KARTI
A15: GÜNLÜK NAKİT
A16: GÜNLÜK KREDİ KARTI
A17: NAKİT VE KREDİ KARTI TOPLAMI
A19: GÜNLÜK KASADAN HARCAMALAR TOPLAMI | D19: =SUM(D21:E33) -> 0
A20: KASA NAKİT HARCAMA DETAYI | B20: AÇIKLAMA | D20: TUTAR
A34: YÖNETİME TESLİM EDİLMESİ GEREKEN NAKİT TUTAR | D34: =D15+D13-D19 -> 0
A35: KASA TESLİMATI AÇIKLAMASI
A36: KASA AÇILIŞI TUTARI | B36: YÖNETİMDEN GELEN TUTAR | C36: KASA ÇIKIŞI | D36: KASADA OLMASI GEREKEN TUTAR | E36: REEL KASA MEVCUDU | F36: ANA KASA KAPANIŞ FARKI
A37: ='20'!E37 -> 3818.48 | C37: =D19 -> 0 | D37: =A37+B37+D15-C37 -> 3818.48 | E37: =D37 -> 3818.48 | F37: =E37-D37 -> 0
A38: CARİ AÇIKLAMASI | B38: DEVİR BAKİYESİ | C38: YENİ ALIM | D38: ÖDEME | E38: SON BAKİYESİ
A39: NURETTİN ATILMIŞ CARİSİ | B39: ='20'!E39 -> 928120 | E39: =B39+C39-D39 -> 928120
A40: DAVUL ÜCRETİ CARİSİ | B40: ='20'!E40 -> 0 | E40: =B40+C40-D40 -> 0
A41: ÖDENMEZ İKRAM TOPLAMI | E41: =SUM(E43:E68) -> 0
A42: ÖDENMEZ İKRAMI KULLANAN ADI SAYADI | B42: ÇEK NO | C42: ÇEKİN İÇERİĞİ (ÜRÜN DETAYI | E42: ÖDENMEZİN TOPLAM TUTARI
A70: İŞLETME GİDERLERİ DETAYI | B70: TUTAR
A71: SANATÇI GİDERİ
A72: TEKNİK EKİPMAN GİDERLERİ
A73: MATMAZEL COCO
A74: YEMEK GİDERİ BİRLİK GIDA 190 KİŞİ (KISİ BASI KDV DAHIL 880 TL )
A75: İÇECEK KDV Sİ | B75: =B77*0.1568 -> 0
A76: %10 SERVİS ÜCRETİ ÖDENECEK TUTAR
A77: İÇECEK SATIŞ VE ÖDENMEZ MALİYETİ
A78: =A19 -> GÜNLÜK KASADAN HARCAMALAR TOPLAMI | B78: =D19 -> 0
A79: PERSONEL YEMEK 35 ADET
A81: İŞLETME GİDERLERİ | B81: =SUM(B71:B80) -> 0 | C81: =E2-B81 -> 0 | H81: Gn. Toplam | I81: =SUM(I3:I77) -> 0
H82: FARK | I82: =I81-E41 -> 0
...

Sheet 22
A1: ='21'!A1+1 -> 46195 | B1: ='1'!B1:E1 -> DADA SALON KABARETT GÜN SONU RAPORU
C2: GÜNLÜK TOPLAM CİRO | E2: =D4+D5+D6+D7+D8+D9+D10+D11+D12 -> 0 | G2: ÜRÜN DETAYI | H2: ÖDENMEZ İKRAMI KULLANAN ADI SAYADI | I2: ÖDENMEZİN TOPLAM TUTARI
A3: KUVER SAYISI TOPLAMI | D3: ORT.K.BAŞI FİYAT | E3: =E2/C3 -> #DIV/0!
A4: TUZ BİBER BİLET
A5: İTİCKET
A6: PASSO BİLET
A7: BİLETİNİ AL
A8: BİLETİNO MÜŞTERİ SAYISI
A9: BİLETİX MÜŞTERİ SAYISI
A10: BU BİLET MÜŞTERİ SAYISI
A11: CARİ HESAP
A12: SALON SATIŞ KİŞİ SAYISI | C12: =C3-C4-C5-C6-C7-C8-C9-C10-C11 -> 0 | D12: =SUM(D13:E16) -> 0
A13: OTOPARK GELİRİ NAKİT
A14: OTOPARK GELİRİ KREDİ KARTI
A15: GÜNLÜK NAKİT
A16: GÜNLÜK KREDİ KARTI
A17: NAKİT VE KREDİ KARTI TOPLAMI
A19: GÜNLÜK KASADAN HARCAMALAR TOPLAMI | D19: =SUM(D21:E33) -> 0
A20: KASA NAKİT HARCAMA DETAYI | B20: AÇIKLAMA | D20: TUTAR
A34: YÖNETİME TESLİM EDİLMESİ GEREKEN NAKİT TUTAR | D34: =D15+D13-D19 -> 0
A35: KASA TESLİMATI AÇIKLAMASI
A36: KASA AÇILIŞI TUTARI | B36: YÖNETİMDEN GELEN TUTAR | C36: KASA ÇIKIŞI | D36: KASADA OLMASI GEREKEN TUTAR | E36: REEL KASA MEVCUDU | F36: ANA KASA KAPANIŞ FARKI
A37: ='21'!E37 -> 3818.48 | C37: =D19 -> 0 | D37: =A37+B37+D15-C37 -> 3818.48 | E37: =D37 -> 3818.48 | F37: =E37-D37 -> 0
A38: CARİ AÇIKLAMASI | B38: DEVİR BAKİYESİ | C38: YENİ ALIM | D38: ÖDEME | E38: SON BAKİYESİ
A39: NURETTİN ATILMIŞ CARİSİ | B39: ='21'!E39 -> 928120 | E39: =B39+C39-D39 -> 928120
A40: DAVUL ÜCRETİ CARİSİ | B40: ='21'!E40 -> 0 | E40: =B40+C40-D40 -> 0
A41: ÖDENMEZ İKRAM TOPLAMI | E41: =SUM(E43:E68) -> 0
A42: ÖDENMEZ İKRAMI KULLANAN ADI SAYADI | B42: ÇEK NO | C42: ÇEKİN İÇERİĞİ (ÜRÜN DETAYI | E42: ÖDENMEZİN TOPLAM TUTARI
A70: İŞLETME GİDERLERİ DETAYI | B70: TUTAR
A71: SANATÇI GİDERİ
A72: TEKNİK EKİPMAN GİDERLERİ
A73: MATMAZEL COCO
A74: YEMEK GİDERİ BIRLIK GIDA 97 SET MENÜ + 1 ORDOVR TABAGI
A75: İÇECEK KDV Sİ | B75: =B77*0.1568 -> 0
A76: %10 SERVİS ÜCRETİ ÖDENECEK TUTAR
A77: İÇECEK SATIŞ VE ÖDENMEZ MALİYETİ | C77: =B77/C3 -> #DIV/0!
A78: =A19 -> GÜNLÜK KASADAN HARCAMALAR TOPLAMI | B78: =D19 -> 0
A79: PERSONEL YEMEK 55 ADET
A81: İŞLETME GİDERLERİ | B81: =SUM(B71:B80) -> 0 | C81: =E2-B81 -> 0 | H81: Gn. Toplam | I81: =SUM(I3:I77) -> 0
H82: FARK | I82: =I81-E41 -> 0
...

Sheet 23
A1: ='22'!A1+1 -> 46196 | B1: ='1'!B1:E1 -> DADA SALON KABARETT GÜN SONU RAPORU
C2: GÜNLÜK TOPLAM CİRO | E2: =D4+D5+D6+D7+D8+D9+D10+D11+D12 -> 0 | G2: ÜRÜN DETAYI | H2: ÖDENMEZ İKRAMI KULLANAN ADI SAYADI | I2: ÖDENMEZİN TOPLAM TUTARI
A3: KUVER SAYISI TOPLAMI | D3: ORT.K.BAŞI FİYAT | E3: =E2/C3 -> #DIV/0!
A4: TUZ BİBER BİLET
A5: İTİCKET
A6: PASSO BİLET
A7: BİLETİNİ AL
A8: BİLETİNO MÜŞTERİ SAYISI
A9: BİLETİX MÜŞTERİ SAYISI
A10: BU BİLET MÜŞTERİ SAYISI
A11: CARİ HESAP
A12: SALON SATIŞ KİŞİ SAYISI | C12: =C3-C4-C5-C6-C7-C8-C9-C10-C11 -> 0 | D12: =SUM(D13:E16) -> 0
A13: OTOPARK GELİRİ NAKİT
A14: OTOPARK GELİRİ KREDİ KARTI
A15: GÜNLÜK NAKİT
A16: GÜNLÜK KREDİ KARTI
A17: NAKİT VE KREDİ KARTI TOPLAMI
A19: GÜNLÜK KASADAN HARCAMALAR TOPLAMI | D19: =SUM(D21:E33) -> 0
A20: KASA NAKİT HARCAMA DETAYI | B20: AÇIKLAMA | D20: TUTAR
A34: YÖNETİME TESLİM EDİLMESİ GEREKEN NAKİT TUTAR | D34: =D15+D13-D19 -> 0
A35: KASA TESLİMATI AÇIKLAMASI
A36: KASA AÇILIŞI TUTARI | B36: YÖNETİMDEN GELEN TUTAR | C36: KASA ÇIKIŞI | D36: KASADA OLMASI GEREKEN TUTAR | E36: REEL KASA MEVCUDU | F36: ANA KASA KAPANIŞ FARKI
A37: ='22'!E37 -> 3818.48 | C37: =D19 -> 0 | D37: =A37+B37+D15-C37 -> 3818.48 | E37: =D37 -> 3818.48 | F37: =E37-D37 -> 0
A38: CARİ AÇIKLAMASI | B38: DEVİR BAKİYESİ | C38: YENİ ALIM | D38: ÖDEME | E38: SON BAKİYESİ
A39: NURETTİN ATILMIŞ CARİSİ | B39: ='22'!E39 -> 928120 | E39: =B39+C39-D39 -> 928120
A40: DAVUL ÜCRETİ CARİSİ | B40: ='22'!E40 -> 0 | C40: 750 | D40: 750 | E40: =B40+C40-D40 -> 0
A41: ÖDENMEZ İKRAM TOPLAMI | E41: =SUM(E43:E68) -> 0
A42: ÖDENMEZ İKRAMI KULLANAN ADI SAYADI | B42: ÇEK NO | C42: ÇEKİN İÇERİĞİ (ÜRÜN DETAYI | E42: ÖDENMEZİN TOPLAM TUTARI
A70: İŞLETME GİDERLERİ DETAYI | B70: TUTAR
A71: SANATÇI GİDERİ
A72: TEKNİK EKİPMAN GİDERLERİ
A73: MATMAZEL COCO
A74: YEMEK GİDERİ
A75: İÇECEK KDV Sİ | B75: =B77*0.1568 -> 0
A76: %10 SERVİS ÜCRETİ ÖDENECEK TUTAR
A77: İÇECEK SATIŞ VE ÖDENMEZ MALİYETİ
A78: =A19 -> GÜNLÜK KASADAN HARCAMALAR TOPLAMI | B78: =D19 -> 0
A79: PERSONEL YEMEK 40 ADET
A81: İŞLETME GİDERLERİ | B81: =SUM(B71:B80) -> 0 | C81: =E2-B81 -> 0 | H81: Gn. Toplam | I81: =SUM(I3:I77) -> 0
H82: FARK | I82: =I81-E41 -> 0
...

Sheet 24
A1: ='23'!A1+1 -> 46197 | B1: ='1'!B1:E1 -> DADA SALON KABARETT GÜN SONU RAPORU
C2: GÜNLÜK TOPLAM CİRO | E2: =D4+D5+D6+D7+D8+D9+D10+D11+D12 -> 0 | G2: ÜRÜN DETAYI | H2: ÖDENMEZ İKRAMI KULLANAN ADI SAYADI | I2: ÖDENMEZİN TOPLAM TUTARI
A3: KUVER SAYISI TOPLAMI | D3: ORT.K.BAŞI FİYAT | E3: =E2/C3 -> #DIV/0!
A4: TUZ BİBER BİLET
A5: İTİCKET
A6: PASSO BİLET
A7: BİLETİNİ AL
A8: BİLETİNO MÜŞTERİ SAYISI
A9: BİLETİX MÜŞTERİ SAYISI
A10: BU BİLET MÜŞTERİ SAYISI
A11: CARİ HESAP
A12: SALON SATIŞ KİŞİ SAYISI | C12: =C3-C4-C5-C6-C7-C8-C9-C10-C11 -> 0 | D12: =SUM(D13:E16) -> 0
A13: OTOPARK GELİRİ NAKİT
A14: OTOPARK GELİRİ KREDİ KARTI
A15: GÜNLÜK NAKİT
A16: GÜNLÜK KREDİ KARTI
A17: NAKİT VE KREDİ KARTI TOPLAMI
A19: GÜNLÜK KASADAN HARCAMALAR TOPLAMI | D19: =SUM(D21:E33) -> 0
A20: KASA NAKİT HARCAMA DETAYI | B20: AÇIKLAMA | D20: TUTAR
A34: YÖNETİME TESLİM EDİLMESİ GEREKEN NAKİT TUTAR | D34: =D15+D13-D19 -> 0
A35: KASA TESLİMATI AÇIKLAMASI
A36: KASA AÇILIŞI TUTARI | B36: YÖNETİMDEN GELEN TUTAR | C36: KASA ÇIKIŞI | D36: KASADA OLMASI GEREKEN TUTAR | E36: REEL KASA MEVCUDU | F36: ANA KASA KAPANIŞ FARKI
A37: ='23'!E37 -> 3818.48 | C37: =D19 -> 0 | D37: =A37+B37+D15-C37 -> 3818.48 | E37: =D37 -> 3818.48 | F37: =E37-D37 -> 0
A38: CARİ AÇIKLAMASI | B38: DEVİR BAKİYESİ | C38: YENİ ALIM | D38: ÖDEME | E38: SON BAKİYESİ
A39: NURETTİN ATILMIŞ CARİSİ | B39: ='23'!E39 -> 928120 | E39: =B39+C39-D39 -> 928120
A40: DAVUL ÜCRETİ CARİSİ | B40: ='23'!E40 -> 0 | E40: =B40+C40-D40 -> 0
A41: ÖDENMEZ İKRAM TOPLAMI | E41: =SUM(E43:E68) -> 0
A42: ÖDENMEZ İKRAMI KULLANAN ADI SAYADI | B42: ÇEK NO | C42: ÇEKİN İÇERİĞİ (ÜRÜN DETAYI | E42: ÖDENMEZİN TOPLAM TUTARI
A70: İŞLETME GİDERLERİ DETAYI | B70: TUTAR
A71: SANATÇI GİDERİ
A72: TEKNİK EKİPMAN GİDERLERİ
A73: MATMAZEL COCO
A74: YEMEK GİDERİ
A75: İÇECEK KDV Sİ | B75: =B77*0.1568 -> 0
A76: %10 SERVİS ÜCRETİ ÖDENECEK TUTAR
A77: İÇECEK SATIŞ VE ÖDENMEZ MALİYETİ
A78: =A19 -> GÜNLÜK KASADAN HARCAMALAR TOPLAMI | B78: =D19 -> 0
A79: PERSONEL YEMEK 40 ADET
A81: İŞLETME GİDERLERİ | B81: =SUM(B71:B80) -> 0 | C81: =E2-B81 -> 0 | H81: Gn. Toplam | I81: =SUM(I3:I77) -> 0
H82: FARK | I82: =I81-E41 -> 0
...

Sheet 25
A1: ='24'!A1+1 -> 46198 | B1: ='1'!B1:E1 -> DADA SALON KABARETT GÜN SONU RAPORU
C2: GÜNLÜK TOPLAM CİRO | E2: =D4+D5+D6+D7+D8+D9+D10+D11+D12 -> 0 | G2: ÜRÜN DETAYI | H2: ÖDENMEZ İKRAMI KULLANAN ADI SAYADI | I2: ÖDENMEZİN TOPLAM TUTARI
A3: KUVER SAYISI TOPLAMI | D3: ORT.K.BAŞI FİYAT | E3: =E2/C3 -> #DIV/0!
A4: TUZ BİBER BİLET
A5: İTİCKET
A6: PASSO BİLET
A7: BİLETİNİ AL
A8: BİLETİNO MÜŞTERİ SAYISI | L8: =10080/80 -> 126
A9: BİLETİX MÜŞTERİ SAYISI
A10: BU BİLET MÜŞTERİ SAYISI
A11: CARİ HESAP
A12: SALON SATIŞ KİŞİ SAYISI | C12: =C3-C4-C5-C6-C7-C8-C9-C10-C11 -> 0 | D12: =SUM(D13:E16) -> 0
A13: OTOPARK GELİRİ NAKİT
A14: OTOPARK GELİRİ KREDİ KARTI | L14: =12400/80 -> 155
A15: GÜNLÜK NAKİT
A16: GÜNLÜK KREDİ KARTI
A17: NAKİT VE KREDİ KARTI TOPLAMI
A19: GÜNLÜK KASADAN HARCAMALAR TOPLAMI | D19: =SUM(D21:E33) -> 0
A20: KASA NAKİT HARCAMA DETAYI | B20: AÇIKLAMA | D20: TUTAR
A34: YÖNETİME TESLİM EDİLMESİ GEREKEN NAKİT TUTAR | D34: =D15+D13-D19 -> 0
A35: KASA TESLİMATI AÇIKLAMASI
A36: KASA AÇILIŞI TUTARI | B36: YÖNETİMDEN GELEN TUTAR | C36: KASA ÇIKIŞI | D36: KASADA OLMASI GEREKEN TUTAR | E36: REEL KASA MEVCUDU | F36: ANA KASA KAPANIŞ FARKI
A37: ='24'!E37 -> 3818.48 | C37: =D19 -> 0 | D37: =A37+B37+D15-C37 -> 3818.48 | E37: =D37 -> 3818.48 | F37: =E37-D37 -> 0
A38: CARİ AÇIKLAMASI | B38: DEVİR BAKİYESİ | C38: YENİ ALIM | D38: ÖDEME | E38: SON BAKİYESİ
A39: NURETTİN ATILMIŞ CARİSİ | B39: ='24'!E39 -> 928120 | E39: =B39+C39-D39 -> 928120
A40: DAVUL ÜCRETİ CARİSİ | B40: ='24'!E40 -> 0 | E40: =B40+C40-D40 -> 0
A41: ÖDENMEZ İKRAM TOPLAMI | E41: =SUM(E43:E68) -> 0
A42: ÖDENMEZ İKRAMI KULLANAN ADI SAYADI | B42: ÇEK NO | C42: ÇEKİN İÇERİĞİ (ÜRÜN DETAYI | E42: ÖDENMEZİN TOPLAM TUTARI
A70: İŞLETME GİDERLERİ DETAYI | B70: TUTAR
A71: SANATÇI GİDERİ
A72: TEKNİK EKİPMAN GİDERLERİ
A73: MATMAZEL COCO
A74: YEMEK GİDERİ
A75: İÇECEK KDV Sİ | B75: =B77*0.1568 -> 0
A76: %10 SERVİS ÜCRETİ ÖDENECEK TUTAR
A77: İÇECEK SATIŞ VE ÖDENMEZ MALİYETİ
A78: =A19 -> GÜNLÜK KASADAN HARCAMALAR TOPLAMI | B78: =D19 -> 0
A79: PERSONEL YEMEK 40 ADET
A81: İŞLETME GİDERLERİ | B81: =SUM(B71:B80) -> 0 | C81: =E2-B81 -> 0 | H81: Gn. Toplam | I81: =SUM(I3:I77) -> 0
H82: FARK | I82: =I81-E41 -> 0
...

Sheet 26
A1: ='25'!A1+1 -> 46199 | B1: ='1'!B1:E1 -> DADA SALON KABARETT GÜN SONU RAPORU
C2: GÜNLÜK TOPLAM CİRO | E2: =D4+D5+D6+D7+D8+D9+D10+D11+D12 -> 0 | G2: ÜRÜN DETAYI | H2: ÖDENMEZ İKRAMI KULLANAN ADI SAYADI | I2: ÖDENMEZİN TOPLAM TUTARI
A3: KUVER SAYISI TOPLAMI | D3: ORT.K.BAŞI FİYAT | E3: =E2/C3 -> #DIV/0!
A4: TUZ BİBER BİLET
A5: İTİCKET
A6: PASSO BİLET
A7: BİLETİNİ AL
A8: BİLETİNO MÜŞTERİ SAYISI
A9: BİLETİX MÜŞTERİ SAYISI
A10: BU BİLET MÜŞTERİ SAYISI
A11: CARİ HESAP
A12: SALON SATIŞ KİŞİ SAYISI | C12: =C3-C4-C5-C6-C7-C8-C9-C10-C11 -> 0 | D12: =SUM(D13:E16) -> 0
A13: OTOPARK GELİRİ NAKİT
A14: OTOPARK GELİRİ KREDİ KARTI
A15: GÜNLÜK NAKİT
A16: GÜNLÜK KREDİ KARTI
A17: NAKİT VE KREDİ KARTI TOPLAMI
A19: GÜNLÜK KASADAN HARCAMALAR TOPLAMI | D19: =SUM(D21:E33) -> 0
A20: KASA NAKİT HARCAMA DETAYI | B20: AÇIKLAMA | D20: TUTAR
A34: YÖNETİME TESLİM EDİLMESİ GEREKEN NAKİT TUTAR | D34: =D15+D13-D19 -> 0
A35: KASA TESLİMATI AÇIKLAMASI
A36: KASA AÇILIŞI TUTARI | B36: YÖNETİMDEN GELEN TUTAR | C36: KASA ÇIKIŞI | D36: KASADA OLMASI GEREKEN TUTAR | E36: REEL KASA MEVCUDU | F36: ANA KASA KAPANIŞ FARKI
A37: ='25'!E37 -> 3818.48 | C37: =D19 -> 0 | D37: =A37+B37+D15-C37 -> 3818.48 | E37: =D37 -> 3818.48 | F37: =E37-D37 -> 0
A38: CARİ AÇIKLAMASI | B38: DEVİR BAKİYESİ | C38: YENİ ALIM | D38: ÖDEME | E38: SON BAKİYESİ
A39: NURETTİN ATILMIŞ CARİSİ | B39: ='25'!E39 -> 928120 | E39: =B39+C39-D39 -> 928120
A40: DAVUL ÜCRETİ CARİSİ | B40: ='25'!E40 -> 0 | E40: =B40+C40-D40 -> 0
A41: ÖDENMEZ İKRAM TOPLAMI | E41: =SUM(E43:E68) -> 0
A42: ÖDENMEZ İKRAMI KULLANAN ADI SAYADI | B42: ÇEK NO | C42: ÇEKİN İÇERİĞİ (ÜRÜN DETAYI | E42: ÖDENMEZİN TOPLAM TUTARI
A70: İŞLETME GİDERLERİ DETAYI | B70: TUTAR
A71: SANATÇI GİDERİ
A72: TEKNİK EKİPMAN GİDERLERİ
A73: MATMAZEL COCO
A74: YEMEK GİDERİ
A75: İÇECEK KDV Sİ | B75: =B77*0.1568 -> 0
A76: %10 SERVİS ÜCRETİ ÖDENECEK TUTAR
A77: İÇECEK SATIŞ VE ÖDENMEZ MALİYETİ
A78: =A19 -> GÜNLÜK KASADAN HARCAMALAR TOPLAMI | B78: =D19 -> 0
A79: PERSONEL YEMEK 40 ADET
A81: İŞLETME GİDERLERİ | B81: =SUM(B71:B80) -> 0 | C81: =E2-B81 -> 0 | H81: Gn. Toplam | I81: =SUM(I3:I77) -> 0
H82: FARK | I82: =I81-E41 -> 0
...

Sheet 27
A1: ='26'!A1+1 -> 46200 | B1: ='1'!B1:E1 -> DADA SALON KABARETT GÜN SONU RAPORU
C2: GÜNLÜK TOPLAM CİRO | E2: =D4+D5+D6+D7+D8+D9+D10+D11+D12 -> 0 | G2: ÜRÜN DETAYI | H2: ÖDENMEZ İKRAMI KULLANAN ADI SAYADI | I2: ÖDENMEZİN TOPLAM TUTARI
A3: KUVER SAYISI TOPLAMI | D3: ORT.K.BAŞI FİYAT | E3: =E2/C3 -> #DIV/0!
A4: TUZ BİBER BİLET
A5: İTİCKET
A6: PASSO BİLET
A7: BİLETİNİ AL
A8: BİLETİNO MÜŞTERİ SAYISI
A9: BİLETİX MÜŞTERİ SAYISI
A10: BU BİLET MÜŞTERİ SAYISI
A11: CARİ HESAP
